Workbook
Name Hours: #REF!
Name Hours: #REF!
Name Hours: #REF!
Name Hours: #REF!
Name Month: Create!$AH$9:$AH$20
Name Tutor: #REF!
Name Tutor: #REF!
Name Tutor: #REF!
Name Tutor: #REF!
Name Year: Create!$AI$9:$AI$39

Sheet Create
AH1: 2 | AI1: 2026
E2: Create data set for selected month and year
D4: Month | E4: Year
AH6: 2 | AI6: 2026
AH8: month | AI8: Year
AH9: 1 | AI9: 2020
AH10: 2 | AI10: 2021
AH11: 3 | AI11: 2022
AH12: 4 | AI12: 2023
AH13: 5 | AI13: 2024
E14: Update Summary sheet | AH14: 6 | AI14: 2025
AH15: 7 | AI15: 2026
AH16: 8 | AI16: 2027
AH17: 9 | AI17: 2028
AH18: 10 | AI18: 2029
AH19: 11 | AI19: 2030
AH20: 12 | AI20: 2031
AI21: 2032
AI22: 2033
AI23: 2034
AI24: 2035
AI25: 2036
AI26: 2037
AI27: 2038
AI28: 2039
AI29: 2040
AI30: 2041
AI31: 2042
AI32: 2043
... AI39: 2050

Sheet Tutor_Names
A1: Sr. No. | B1: Name of Tutors | C1: Category
A2: 1 | B2: Apeksha Bavake | C2: Employee
A3: 2 | B3: Barsha Sahu | C3: C-User
A4: 3 | B4: Bikash Sahoo | C4: CHB
A5: 4 | B5: Deepti Tiwari
A6: 5 | B6: Dipali Chandgude
A7: 6 | B7: Hanumant Lahane
A8: 7 | B8: Laxman
A9: 8 | B9: Meenakshi Devikar
A10: 9 | B10: Nikita Nirmal
A11: 10 | B11: Prasanna Hegde
A12: 11 | B12: Pravin Patil
A13: 12 | B13: Saman Lohar
A14: 13 | B14: Sanghamitra Khairmode
A15: 14 | B15: Santosh Chakraborty
A16: 15 | B16: Vaishnavi Chothe
... A101: 100 | B101: T73

Sheet Online_Wk_6
B1: Time table for February'2026
B2: Week 6
B3: Day Shift (Online)
B4: Time | C4: Hours | K4: Total
D5: Mon | E5: Tue | F5: Wed | G5: Thu | H5: Fri | I5: Sat | J5: Sun
B6: Day Shift | C6: DAYSTART | M6: Sr. No. | N6: Name of Tutor | O6: Day Shift Hours | P6: Night Shift Hours | Q6: Total Hours | V6: =N7 -> Apeksha Bavake | W6: =N8 -> Barsha Sahu | X6: =N9 -> Bikash Sahoo | Y6: =N10 -> Deepti Tiwari | Z6: =N11 -> Dipali Chandgude | AA6: =N12 -> Hanumant Lahane | AB6: =N13 -> Laxman | AC6: =N14 -> Meenakshi Devikar | AD6: =N15 -> Nikita Nirmal | AE6: =N16 -> Prasanna Hegde | AF6: =N17 -> Pravin Patil | AG6: =N18 -> Saman Lohar | AH6: =N19 -> Sanghamitra Khairmode | AI6: =N20 -> Santosh Chakraborty | AJ6: =N21 -> Vaishnavi Chothe | AK6: =N22 -> Vishakha Sali | AL6: =N23 -> T4 | AM6: =N24 -> T5 | AN6: =N25 -> T6 | AO6: =N26 -> T7 | AP6: =N27 -> T8 | AQ6: =N28 -> T9 | AR6: =N29 -> T10 | AS6: =N30 -> T11 | AT6: =N31 -> T12 | AU6: =N32 -> X | AV6: =N33 -> Apeksha Bavake (Instant) | AW6: =N34 -> Barsha Sahu (Instant) | AX6: =N35 -> Bikash Sahoo (Instant) | AY6: =N36 -> Deepti Tiwari (Instant) | AZ6: =N37 -> Dipali Chandgude (Instant) | BA6: =N38 -> Hanumant Lahane (Instant) | BB6: =N39 -> Laxman (Instant) | BC6: =N40 -> Meenakshi Devikar (Instant) | BD6: =N41 -> Nikita Nirmal (Instant) | BE6: =N42 -> Prasanna Hegde (Instant) | BF6: =N43 -> Pravin Patil (Instant) | BG6: =N44 -> Saman Lohar (Instant) | BH6: =N45 -> Sanghamitra Khairmode (Instant) | BI6: =N46 -> Santosh Chakraborty (Instant) | BJ6: =N47 -> Vaishnavi Chothe (Instant) | BK6: =N48 -> Vishakha Sali (Instant) | BL6: =N49 -> T16 | BM6: =N50 -> T17 | BN6: =N51 -> T18 | BO6: =N52 -> T19 | BP6: =N53 -> T20 | BQ6: =N54 -> T21 | BR6: =N55 -> T22 | BS6: =N56 -> T23 | BT6: =N57 -> T24 | BU6: =N58 -> T25 | BV6: =N59 -> T26 | BW6: =N60 -> T27 | BX6: =N61 -> T28 | BY6: =N62 -> T29 | BZ6: =N63 -> T30 | CA6: =N64 -> T31 | CB6: =N65 -> T32 | CC6: =N66 -> T33 | CD6: =N67 -> T34 | CE6: =N68 -> T35 | CF6: =N69 -> T36 | CG6: =N70 -> T37 | CH6: =N71 -> T38 | CI6: =N72 -> T39 | CJ6: =N73 -> T40 | CK6: =N74 -> T41 | CL6: =N75 -> T42 | CM6: =N76 -> T43 | CN6: =N77 -> T44 | CO6: =N78 -> T45 | CP6: =N79 -> T46 | CQ6: =N80 -> T47 | CR6: =N81 -> T48 | CS6: =N82 -> T49 | CT6: =N83 -> T50 | CU6: =N84 -> T51 | CV6: =N85 -> T52 | CW6: =N86 -> T53 | CX6: =N87 -> T54 | CY6: =N88 -> T55 | CZ6: =N89 -> T56 | DA6: =N90 -> T57 | DB6: =N91 -> T58 | DC6: =N92 -> T59 | DD6: =N93 -> T60 | DE6: =N94 -> T61 | DF6: =N94 -> T61 | DG6: =N95 -> T62 | DH6: =N96 -> T63 | DI6: =N96 -> T63 | DJ6: =N97 -> T64 | DK6: =N98 -> T65 | DL6: =N99 -> T66 | DM6: =N100 -> T67 | DN6: =N101 -> T68 | DO6: =N102 -> T69 | DP6: =N103 -> T70 | DQ6: =N104 -> T71 | DR6: =N105 -> T72 | DS6: =N106 -> T73
K7: =COUNTA(D7:J7)*C7 -> 0 | M7: 1 | N7: =Tutor_Names!B2 -> Apeksha Bavake | O7: =HLOOKUP($N7,$V$6:$DS$107,102,FALSE) -> 0 | P7: =HLOOKUP($N7,$V$115:$DS$216,102,FALSE) -> 0 | Q7: =SUM(O7:P7) -> 0 | V7: =COUNTIF($D7:$J7,V$6)*$C7 -> 0 | W7: =COUNTIF($D7:$J7,W$6)*$C7 -> 0 | X7: =COUNTIF($D7:$J7,X$6)*$C7 -> 0 | Y7: =COUNTIF($D7:$J7,Y$6)*$C7 -> 0 | Z7: =COUNTIF($D7:$J7,Z$6)*$C7 -> 0 | AA7: =COUNTIF($D7:$J7,AA$6)*$C7 -> 0 | AB7: =COUNTIF($D7:$J7,AB$6)*$C7 -> 0 | AC7: =COUNTIF($D7:$J7,AC$6)*$C7 -> 0 | ... DS7: =COUNTIF($D7:$J7,DS$6)*$C7 -> 0
K8: =COUNTA(D8:J8)*C8 -> 0 | M8: =M7+1 -> 2 | N8: =Tutor_Names!B3 -> Barsha Sahu | O8: =HLOOKUP($N8,$V$6:$DS$107,102,FALSE) -> 0 | P8: =HLOOKUP($N8,$V$115:$DS$216,102,FALSE) -> 0 | Q8: =SUM(O8:P8) -> 0 | V8: =COUNTIF($D8:$J8,V$6)*$C8 -> 0 | W8: =COUNTIF($D8:$J8,W$6)*$C8 -> 0 | X8: =COUNTIF($D8:$J8,X$6)*$C8 -> 0 | Y8: =COUNTIF($D8:$J8,Y$6)*$C8 -> 0 | Z8: =COUNTIF($D8:$J8,Z$6)*$C8 -> 0 | AA8: =COUNTIF($D8:$J8,AA$6)*$C8 -> 0 | AB8: =COUNTIF($D8:$J8,AB$6)*$C8 -> 0 | AC8: =COUNTIF($D8:$J8,AC$6)*$C8 -> 0 | ... DS8: =COUNTIF($D8:$J8,DS$6)*$C8 -> 0
K9: =COUNTA(D9:J9)*C9 -> 0 | M9: =M8+1 -> 3 | N9: =Tutor_Names!B4 -> Bikash Sahoo | O9: =HLOOKUP($N9,$V$6:$DS$107,102,FALSE) -> 0 | P9: =HLOOKUP($N9,$V$115:$DS$216,102,FALSE) -> 0 | Q9: =SUM(O9:P9) -> 0 | V9: =COUNTIF($D9:$J9,V$6)*$C9 -> 0 | W9: =COUNTIF($D9:$J9,W$6)*$C9 -> 0 | X9: =COUNTIF($D9:$J9,X$6)*$C9 -> 0 | Y9: =COUNTIF($D9:$J9,Y$6)*$C9 -> 0 | Z9: =COUNTIF($D9:$J9,Z$6)*$C9 -> 0 | AA9: =COUNTIF($D9:$J9,AA$6)*$C9 -> 0 | AB9: =COUNTIF($D9:$J9,AB$6)*$C9 -> 0 | AC9: =COUNTIF($D9:$J9,AC$6)*$C9 -> 0 | ... DS9: =COUNTIF($D9:$J9,DS$6)*$C9 -> 0
K10: =COUNTA(D10:J10)*C10 -> 0 | M10: =M9+1 -> 4 | N10: =Tutor_Names!B5 -> Deepti Tiwari | O10: =HLOOKUP($N10,$V$6:$DS$107,102,FALSE) -> 0 | P10: =HLOOKUP($N10,$V$115:$DS$216,102,FALSE) -> 0 | Q10: =SUM(O10:P10) -> 0 | V10: =COUNTIF($D10:$J10,V$6)*$C10 -> 0 | W10: =COUNTIF($D10:$J10,W$6)*$C10 -> 0 | X10: =COUNTIF($D10:$J10,X$6)*$C10 -> 0 | Y10: =COUNTIF($D10:$J10,Y$6)*$C10 -> 0 | Z10: =COUNTIF($D10:$J10,Z$6)*$C10 -> 0 | AA10: =COUNTIF($D10:$J10,AA$6)*$C10 -> 0 | AB10: =COUNTIF($D10:$J10,AB$6)*$C10 -> 0 | AC10: =COUNTIF($D10:$J10,AC$6)*$C10 -> 0 | ... DS10: =COUNTIF($D10:$J10,DS$6)*$C10 -> 0
K11: =COUNTA(D11:J11)*C11 -> 0 | M11: =M10+1 -> 5 | N11: =Tutor_Names!B6 -> Dipali Chandgude | O11: =HLOOKUP($N11,$V$6:$DS$107,102,FALSE) -> 0 | P11: =HLOOKUP($N11,$V$115:$DS$216,102,FALSE) -> 0 | Q11: =SUM(O11:P11) -> 0 | V11: =COUNTIF($D11:$J11,V$6)*$C11 -> 0 | W11: =COUNTIF($D11:$J11,W$6)*$C11 -> 0 | X11: =COUNTIF($D11:$J11,X$6)*$C11 -> 0 | Y11: =COUNTIF($D11:$J11,Y$6)*$C11 -> 0 | Z11: =COUNTIF($D11:$J11,Z$6)*$C11 -> 0 | AA11: =COUNTIF($D11:$J11,AA$6)*$C11 -> 0 | AB11: =COUNTIF($D11:$J11,AB$6)*$C11 -> 0 | AC11: =COUNTIF($D11:$J11,AC$6)*$C11 -> 0 | ... DS11: =COUNTIF($D11:$J11,DS$6)*$C11 -> 0
K12: =COUNTA(D12:J12)*C12 -> 0 | M12: =M11+1 -> 6 | N12: =Tutor_Names!B7 -> Hanumant Lahane | O12: =HLOOKUP($N12,$V$6:$DS$107,102,FALSE) -> 0 | P12: =HLOOKUP($N12,$V$115:$DS$216,102,FALSE) -> 0 | Q12: =SUM(O12:P12) -> 0 | V12: =COUNTIF($D12:$J12,V$6)*$C12 -> 0 | W12: =COUNTIF($D12:$J12,W$6)*$C12 -> 0 | X12: =COUNTIF($D12:$J12,X$6)*$C12 -> 0 | Y12: =COUNTIF($D12:$J12,Y$6)*$C12 -> 0 | Z12: =COUNTIF($D12:$J12,Z$6)*$C12 -> 0 | AA12: =COUNTIF($D12:$J12,AA$6)*$C12 -> 0 | AB12: =COUNTIF($D12:$J12,AB$6)*$C12 -> 0 | AC12: =COUNTIF($D12:$J12,AC$6)*$C12 -> 0 | ... DS12: =COUNTIF($D12:$J12,DS$6)*$C12 -> 0
K13: =COUNTA(D13:J13)*C13 -> 0 | M13: =M12+1 -> 7 | N13: =Tutor_Names!B8 -> Laxman | O13: =HLOOKUP($N13,$V$6:$DS$107,102,FALSE) -> 0 | P13: =HLOOKUP($N13,$V$115:$DS$216,102,FALSE) -> 0 | Q13: =SUM(O13:P13) -> 0 | V13: =COUNTIF($D13:$J13,V$6)*$C13 -> 0 | W13: =COUNTIF($D13:$J13,W$6)*$C13 -> 0 | X13: =COUNTIF($D13:$J13,X$6)*$C13 -> 0 | Y13: =COUNTIF($D13:$J13,Y$6)*$C13 -> 0 | Z13: =COUNTIF($D13:$J13,Z$6)*$C13 -> 0 | AA13: =COUNTIF($D13:$J13,AA$6)*$C13 -> 0 | AB13: =COUNTIF($D13:$J13,AB$6)*$C13 -> 0 | AC13: =COUNTIF($D13:$J13,AC$6)*$C13 -> 0 | ... DS13: =COUNTIF($D13:$J13,DS$6)*$C13 -> 0
K14: =COUNTA(D14:J14)*C14 -> 0 | M14: =M13+1 -> 8 | N14: =Tutor_Names!B9 -> Meenakshi Devikar | O14: =HLOOKUP($N14,$V$6:$DS$107,102,FALSE) -> 0 | P14: =HLOOKUP($N14,$V$115:$DS$216,102,FALSE) -> 0 | Q14: =SUM(O14:P14) -> 0 | V14: =COUNTIF($D14:$J14,V$6)*$C14 -> 0 | W14: =COUNTIF($D14:$J14,W$6)*$C14 -> 0 | X14: =COUNTIF($D14:$J14,X$6)*$C14 -> 0 | Y14: =COUNTIF($D14:$J14,Y$6)*$C14 -> 0 | Z14: =COUNTIF($D14:$J14,Z$6)*$C14 -> 0 | AA14: =COUNTIF($D14:$J14,AA$6)*$C14 -> 0 | AB14: =COUNTIF($D14:$J14,AB$6)*$C14 -> 0 | AC14: =COUNTIF($D14:$J14,AC$6)*$C14 -> 0 | ... DS14: =COUNTIF($D14:$J14,DS$6)*$C14 -> 0
K15: =COUNTA(D15:J15)*C15 -> 0 | M15: =M14+1 -> 9 | N15: =Tutor_Names!B10 -> Nikita Nirmal | O15: =HLOOKUP($N15,$V$6:$DS$107,102,FALSE) -> 0 | P15: =HLOOKUP($N15,$V$115:$DS$216,102,FALSE) -> 0 | Q15: =SUM(O15:P15) -> 0 | V15: =COUNTIF($D15:$J15,V$6)*$C15 -> 0 | W15: =COUNTIF($D15:$J15,W$6)*$C15 -> 0 | X15: =COUNTIF($D15:$J15,X$6)*$C15 -> 0 | Y15: =COUNTIF($D15:$J15,Y$6)*$C15 -> 0 | Z15: =COUNTIF($D15:$J15,Z$6)*$C15 -> 0 | AA15: =COUNTIF($D15:$J15,AA$6)*$C15 -> 0 | AB15: =COUNTIF($D15:$J15,AB$6)*$C15 -> 0 | AC15: =COUNTIF($D15:$J15,AC$6)*$C15 -> 0 | ... DS15: =COUNTIF($D15:$J15,DS$6)*$C15 -> 0
K16: =COUNTA(D16:J16)*C16 -> 0 | M16: =M15+1 -> 10 | N16: =Tutor_Names!B11 -> Prasanna Hegde | O16: =HLOOKUP($N16,$V$6:$DS$107,102,FALSE) -> 0 | P16: =HLOOKUP($N16,$V$115:$DS$216,102,FALSE) -> 0 | Q16: =SUM(O16:P16) -> 0 | V16: =COUNTIF($D16:$J16,V$6)*$C16 -> 0 | W16: =COUNTIF($D16:$J16,W$6)*$C16 -> 0 | X16: =COUNTIF($D16:$J16,X$6)*$C16 -> 0 | Y16: =COUNTIF($D16:$J16,Y$6)*$C16 -> 0 | Z16: =COUNTIF($D16:$J16,Z$6)*$C16 -> 0 | AA16: =COUNTIF($D16:$J16,AA$6)*$C16 -> 0 | AB16: =COUNTIF($D16:$J16,AB$6)*$C16 -> 0 | AC16: =COUNTIF($D16:$J16,AC$6)*$C16 -> 0 | ... DS16: =COUNTIF($D16:$J16,DS$6)*$C16 -> 0
K17: =COUNTA(D17:J17)*C17 -> 0 | M17: =M16+1 -> 11 | N17: =Tutor_Names!B12 -> Pravin Patil | O17: =HLOOKUP($N17,$V$6:$DS$107,102,FALSE) -> 0 | P17: =HLOOKUP($N17,$V$115:$DS$216,102,FALSE) -> 0 | Q17: =SUM(O17:P17) -> 0 | V17: =COUNTIF($D17:$J17,V$6)*$C17 -> 0 | W17: =COUNTIF($D17:$J17,W$6)*$C17 -> 0 | X17: =COUNTIF($D17:$J17,X$6)*$C17 -> 0 | Y17: =COUNTIF($D17:$J17,Y$6)*$C17 -> 0 | Z17: =COUNTIF($D17:$J17,Z$6)*$C17 -> 0 | AA17: =COUNTIF($D17:$J17,AA$6)*$C17 -> 0 | AB17: =COUNTIF($D17:$J17,AB$6)*$C17 -> 0 | AC17: =COUNTIF($D17:$J17,AC$6)*$C17 -> 0 | ... DS17: =COUNTIF($D17:$J17,DS$6)*$C17 -> 0
K18: =COUNTA(D18:J18)*C18 -> 0 | M18: =M17+1 -> 12 | N18: =Tutor_Names!B13 -> Saman Lohar | O18: =HLOOKUP($N18,$V$6:$DS$107,102,FALSE) -> 0 | P18: =HLOOKUP($N18,$V$115:$DS$216,102,FALSE) -> 0 | Q18: =SUM(O18:P18) -> 0 | V18: =COUNTIF($D18:$J18,V$6)*$C18 -> 0 | W18: =COUNTIF($D18:$J18,W$6)*$C18 -> 0 | X18: =COUNTIF($D18:$J18,X$6)*$C18 -> 0 | Y18: =COUNTIF($D18:$J18,Y$6)*$C18 -> 0 | Z18: =COUNTIF($D18:$J18,Z$6)*$C18 -> 0 | AA18: =COUNTIF($D18:$J18,AA$6)*$C18 -> 0 | AB18: =COUNTIF($D18:$J18,AB$6)*$C18 -> 0 | AC18: =COUNTIF($D18:$J18,AC$6)*$C18 -> 0 | ... DS18: =COUNTIF($D18:$J18,DS$6)*$C18 -> 0
K19: =COUNTA(D19:J19)*C19 -> 0 | M19: =M18+1 -> 13 | N19: =Tutor_Names!B14 -> Sanghamitra Khairmode | O19: =HLOOKUP($N19,$V$6:$DS$107,102,FALSE) -> 0 | P19: =HLOOKUP($N19,$V$115:$DS$216,102,FALSE) -> 0 | Q19: =SUM(O19:P19) -> 0 | V19: =COUNTIF($D19:$J19,V$6)*$C19 -> 0 | W19: =COUNTIF($D19:$J19,W$6)*$C19 -> 0 | X19: =COUNTIF($D19:$J19,X$6)*$C19 -> 0 | Y19: =COUNTIF($D19:$J19,Y$6)*$C19 -> 0 | Z19: =COUNTIF($D19:$J19,Z$6)*$C19 -> 0 | AA19: =COUNTIF($D19:$J19,AA$6)*$C19 -> 0 | AB19: =COUNTIF($D19:$J19,AB$6)*$C19 -> 0 | AC19: =COUNTIF($D19:$J19,AC$6)*$C19 -> 0 | ... DS19: =COUNTIF($D19:$J19,DS$6)*$C19 -> 0
... K106: =COUNTA(D106:J106)*C106 -> 0 | M106: =M105+1 -> 100 | N106: =Tutor_Names!B101 -> T73 | O106: =HLOOKUP($N106,$V$6:$DS$107,102,FALSE) -> 0 | P106: =HLOOKUP($N106,$V$115:$DS$216,102,FALSE) -> 0 | Q106: =SUM(O106:P106) -> 0 | V106: =COUNTIF($D106:$J106,V$6)*$C106 -> 0 | W106: =COUNTIF($D106:$J106,W$6)*$C106 -> 0 | X106: =COUNTIF($D106:$J106,X$6)*$C106 -> 0 | Y106: =COUNTIF($D106:$J106,Y$6)*$C106 -> 0 | Z106: =COUNTIF($D106:$J106,Z$6)*$C106 -> 0 | AA106: =COUNTIF($D106:$J106,AA$6)*$C106 -> 0 | AB106: =COUNTIF($D106:$J106,AB$6)*$C106 -> 0 | AC106: =COUNTIF($D106:$J106,AC$6)*$C106 -> 0 | ... DS106: =COUNTIF($D106:$J106,DS$6)*$C106 -> 0
C107: DAYEND | K107: =SUM(K7:K106) -> 0 | M107: Total | O107: =SUM(O7:O106) -> 0 | P107: =SUM(P7:P106) -> 0 | Q107: =SUM(O107:P107) -> 0 | V107: =SUM(V7:V106) -> 0 | W107: =SUM(W7:W106) -> 0 | X107: =SUM(X7:X106) -> 0 | Y107: =SUM(Y7:Y106) -> 0 | Z107: =SUM(Z7:Z106) -> 0 | AA107: =SUM(AA7:AA106) -> 0 | AB107: =SUM(AB7:AB106) -> 0 | AC107: =SUM(AC7:AC106) -> 0 | ... DS107: =SUM(DS7:DS106) -> 0
B111: =B2 -> Week 6
B112: Night Shift
B113: Time | C113: Hours | D113: =D4 -> 0 | E113: =E4 -> 0 | F113: =F4 -> 0 | G113: =G4 -> 0 | H113: =H4 -> 0 | I113: =I4 -> 0 | J113: =J4 -> 0 | K113: Total
D114: Mon | E114: Tue | F114: Wed | G114: Thu | H114: Fri | I114: Sat | J114: Sun
B115: Night Shift | C115: NIGHTSTART | V115: =V6 -> Apeksha Bavake | W115: =W6 -> Barsha Sahu | X115: =X6 -> Bikash Sahoo | Y115: =Y6 -> Deepti Tiwari | Z115: =Z6 -> Dipali Chandgude | AA115: =AA6 -> Hanumant Lahane | AB115: =AB6 -> Laxman | AC115: =AC6 -> Meenakshi Devikar | ... DS115: =DS6 -> T73
K116: =COUNTA(D116:J116)*C116 -> 0 | V116: =COUNTIF($D116:$J116,V$6)*$C116 -> 0 | W116: =COUNTIF($D116:$J116,W$6)*$C116 -> 0 | X116: =COUNTIF($D116:$J116,X$6)*$C116 -> 0 | Y116: =COUNTIF($D116:$J116,Y$6)*$C116 -> 0 | Z116: =COUNTIF($D116:$J116,Z$6)*$C116 -> 0 | AA116: =COUNTIF($D116:$J116,AA$6)*$C116 -> 0 | AB116: =COUNTIF($D116:$J116,AB$6)*$C116 -> 0 | AC116: =COUNTIF($D116:$J116,AC$6)*$C116 -> 0 | ... DS116: =COUNTIF($D116:$J116,DS$6)*$C116 -> 0
K117: =COUNTA(D117:J117)*C117 -> 0 | V117: =COUNTIF($D117:$J117,V$6)*$C117 -> 0 | W117: =COUNTIF($D117:$J117,W$6)*$C117 -> 0 | X117: =COUNTIF($D117:$J117,X$6)*$C117 -> 0 | Y117: =COUNTIF($D117:$J117,Y$6)*$C117 -> 0 | Z117: =COUNTIF($D117:$J117,Z$6)*$C117 -> 0 | AA117: =COUNTIF($D117:$J117,AA$6)*$C117 -> 0 | AB117: =COUNTIF($D117:$J117,AB$6)*$C117 -> 0 | AC117: =COUNTIF($D117:$J117,AC$6)*$C117 -> 0 | ... DS117: =COUNTIF($D117:$J117,DS$6)*$C117 -> 0
K118: =COUNTA(D118:J118)*C118 -> 0 | V118: =COUNTIF($D118:$J118,V$6)*$C118 -> 0 | W118: =COUNTIF($D118:$J118,W$6)*$C118 -> 0 | X118: =COUNTIF($D118:$J118,X$6)*$C118 -> 0 | Y118: =COUNTIF($D118:$J118,Y$6)*$C118 -> 0 | Z118: =COUNTIF($D118:$J118,Z$6)*$C118 -> 0 | AA118: =COUNTIF($D118:$J118,AA$6)*$C118 -> 0 | AB118: =COUNTIF($D118:$J118,AB$6)*$C118 -> 0 | AC118: =COUNTIF($D118:$J118,AC$6)*$C118 -> 0 | ... DS118: =COUNTIF($D118:$J118,DS$6)*$C118 -> 0
K119: =COUNTA(D119:J119)*C119 -> 0 | V119: =COUNTIF($D119:$J119,V$6)*$C119 -> 0 | W119: =COUNTIF($D119:$J119,W$6)*$C119 -> 0 | X119: =COUNTIF($D119:$J119,X$6)*$C119 -> 0 | Y119: =COUNTIF($D119:$J119,Y$6)*$C119 -> 0 | Z119: =COUNTIF($D119:$J119,Z$6)*$C119 -> 0 | AA119: =COUNTIF($D119:$J119,AA$6)*$C119 -> 0 | AB119: =COUNTIF($D119:$J119,AB$6)*$C119 -> 0 | AC119: =COUNTIF($D119:$J119,AC$6)*$C119 -> 0 | ... DS119: =COUNTIF($D119:$J119,DS$6)*$C119 -> 0
K120: =COUNTA(D120:J120)*C120 -> 0 | V120: =COUNTIF($D120:$J120,V$6)*$C120 -> 0 | W120: =COUNTIF($D120:$J120,W$6)*$C120 -> 0 | X120: =COUNTIF($D120:$J120,X$6)*$C120 -> 0 | Y120: =COUNTIF($D120:$J120,Y$6)*$C120 -> 0 | Z120: =COUNTIF($D120:$J120,Z$6)*$C120 -> 0 | AA120: =COUNTIF($D120:$J120,AA$6)*$C120 -> 0 | AB120: =COUNTIF($D120:$J120,AB$6)*$C120 -> 0 | AC120: =COUNTIF($D120:$J120,AC$6)*$C120 -> 0 | ... DS120: =COUNTIF($D120:$J120,DS$6)*$C120 -> 0
K121: =COUNTA(D121:J121)*C121 -> 0 | V121: =COUNTIF($D121:$J121,V$6)*$C121 -> 0 | W121: =COUNTIF($D121:$J121,W$6)*$C121 -> 0 | X121: =COUNTIF($D121:$J121,X$6)*$C121 -> 0 | Y121: =COUNTIF($D121:$J121,Y$6)*$C121 -> 0 | Z121: =COUNTIF($D121:$J121,Z$6)*$C121 -> 0 | AA121: =COUNTIF($D121:$J121,AA$6)*$C121 -> 0 | AB121: =COUNTIF($D121:$J121,AB$6)*$C121 -> 0 | AC121: =COUNTIF($D121:$J121,AC$6)*$C121 -> 0 | ... DS121: =COUNTIF($D121:$J121,DS$6)*$C121 -> 0
K122: =COUNTA(D122:J122)*C122 -> 0 | V122: =COUNTIF($D122:$J122,V$6)*$C122 -> 0 | W122: =COUNTIF($D122:$J122,W$6)*$C122 -> 0 | X122: =COUNTIF($D122:$J122,X$6)*$C122 -> 0 | Y122: =COUNTIF($D122:$J122,Y$6)*$C122 -> 0 | Z122: =COUNTIF($D122:$J122,Z$6)*$C122 -> 0 | AA122: =COUNTIF($D122:$J122,AA$6)*$C122 -> 0 | AB122: =COUNTIF($D122:$J122,AB$6)*$C122 -> 0 | AC122: =COUNTIF($D122:$J122,AC$6)*$C122 -> 0 | ... DS122: =COUNTIF($D122:$J122,DS$6)*$C122 -> 0
K123: =COUNTA(D123:J123)*C123 -> 0 | V123: =COUNTIF($D123:$J123,V$6)*$C123 -> 0 | W123: =COUNTIF($D123:$J123,W$6)*$C123 -> 0 | X123: =COUNTIF($D123:$J123,X$6)*$C123 -> 0 | Y123: =COUNTIF($D123:$J123,Y$6)*$C123 -> 0 | Z123: =COUNTIF($D123:$J123,Z$6)*$C123 -> 0 | AA123: =COUNTIF($D123:$J123,AA$6)*$C123 -> 0 | AB123: =COUNTIF($D123:$J123,AB$6)*$C123 -> 0 | AC123: =COUNTIF($D123:$J123,AC$6)*$C123 -> 0 | ... DS123: =COUNTIF($D123:$J123,DS$6)*$C123 -> 0
K124: =COUNTA(D124:J124)*C124 -> 0 | V124: =COUNTIF($D124:$J124,V$6)*$C124 -> 0 | W124: =COUNTIF($D124:$J124,W$6)*$C124 -> 0 | X124: =COUNTIF($D124:$J124,X$6)*$C124 -> 0 | Y124: =COUNTIF($D124:$J124,Y$6)*$C124 -> 0 | Z124: =COUNTIF($D124:$J124,Z$6)*$C124 -> 0 | AA124: =COUNTIF($D124:$J124,AA$6)*$C124 -> 0 | AB124: =COUNTIF($D124:$J124,AB$6)*$C124 -> 0 | AC124: =COUNTIF($D124:$J124,AC$6)*$C124 -> 0 | ... DS124: =COUNTIF($D124:$J124,DS$6)*$C124 -> 0
K125: =COUNTA(D125:J125)*C125 -> 0 | V125: =COUNTIF($D125:$J125,V$6)*$C125 -> 0 | W125: =COUNTIF($D125:$J125,W$6)*$C125 -> 0 | X125: =COUNTIF($D125:$J125,X$6)*$C125 -> 0 | Y125: =COUNTIF($D125:$J125,Y$6)*$C125 -> 0 | Z125: =COUNTIF($D125:$J125,Z$6)*$C125 -> 0 | AA125: =COUNTIF($D125:$J125,AA$6)*$C125 -> 0 | AB125: =COUNTIF($D125:$J125,AB$6)*$C125 -> 0 | AC125: =COUNTIF($D125:$J125,AC$6)*$C125 -> 0 | ... DS125: =COUNTIF($D125:$J125,DS$6)*$C125 -> 0
K126: =COUNTA(D126:J126)*C126 -> 0 | V126: =COUNTIF($D126:$J126,V$6)*$C126 -> 0 | W126: =COUNTIF($D126:$J126,W$6)*$C126 -> 0 | X126: =COUNTIF($D126:$J126,X$6)*$C126 -> 0 | Y126: =COUNTIF($D126:$J126,Y$6)*$C126 -> 0 | Z126: =COUNTIF($D126:$J126,Z$6)*$C126 -> 0 | AA126: =COUNTIF($D126:$J126,AA$6)*$C126 -> 0 | AB126: =COUNTIF($D126:$J126,AB$6)*$C126 -> 0 | AC126: =COUNTIF($D126:$J126,AC$6)*$C126 -> 0 | ... DS126: =COUNTIF($D126:$J126,DS$6)*$C126 -> 0
K127: =COUNTA(D127:J127)*C127 -> 0 | V127: =COUNTIF($D127:$J127,V$6)*$C127 -> 0 | W127: =COUNTIF($D127:$J127,W$6)*$C127 -> 0 | X127: =COUNTIF($D127:$J127,X$6)*$C127 -> 0 | Y127: =COUNTIF($D127:$J127,Y$6)*$C127 -> 0 | Z127: =COUNTIF($D127:$J127,Z$6)*$C127 -> 0 | AA127: =COUNTIF($D127:$J127,AA$6)*$C127 -> 0 | AB127: =COUNTIF($D127:$J127,AB$6)*$C127 -> 0 | AC127: =COUNTIF($D127:$J127,AC$6)*$C127 -> 0 | ... DS127: =COUNTIF($D127:$J127,DS$6)*$C127 -> 0
... K215: =COUNTA(D215:J215)*C215 -> 0 | V215: =COUNTIF($D215:$J215,V$6)*$C215 -> 0 | W215: =COUNTIF($D215:$J215,W$6)*$C215 -> 0 | X215: =COUNTIF($D215:$J215,X$6)*$C215 -> 0 | Y215: =COUNTIF($D215:$J215,Y$6)*$C215 -> 0 | Z215: =COUNTIF($D215:$J215,Z$6)*$C215 -> 0 | AA215: =COUNTIF($D215:$J215,AA$6)*$C215 -> 0 | AB215: =COUNTIF($D215:$J215,AB$6)*$C215 -> 0 | AC215: =COUNTIF($D215:$J215,AC$6)*$C215 -> 0 | ... DS215: =COUNTIF($D215:$J215,DS$6)*$C215 -> 0
C216: NIGHTEND | K216: =SUM(K116:K215) -> 0 | V216: =SUM(V116:V215) -> 0 | W216: =SUM(W116:W215) -> 0 | X216: =SUM(X116:X215) -> 0 | Y216: =SUM(Y116:Y215) -> 0 | Z216: =SUM(Z116:Z215) -> 0 | AA216: =SUM(AA116:AA215) -> 0 | AB216: =SUM(AB116:AB215) -> 0 | AC216: =SUM(AC116:AC215) -> 0 | ... DS216: =SUM(DS116:DS215) -> 0

Sheet PreSch_Wk_1
B1: =#REF! -> #REF!
B2: Week 1
B3: Day Shift (Pre-Scheduled)
B4: Time | C4: Hours | J4: 46054 | K4: Total
D5: Mon | E5: Tue | F5: Wed | G5: Thu | H5: Fri | I5: Sat | J5: Sun
B6: Day Shift | C6: DAYSTART | M6: Sr. No. | N6: Name of Tutor | O6: Day Shift Hours | P6: Night Shift Hours | Q6: Total Hours | V6: =N7 -> Apeksha Bavake | W6: =N8 -> Barsha Sahu | X6: =N9 -> Bikash Sahoo | Y6: =N10 -> Deepti Tiwari | Z6: =N11 -> Dipali Chandgude | AA6: =N12 -> Hanumant Lahane | AB6: =N13 -> Laxman | AC6: =N14 -> Meenakshi Devikar | AD6: =N15 -> Nikita Nirmal | AE6: =N16 -> Prasanna Hegde | AF6: =N17 -> Pravin Patil | AG6: =N18 -> Saman Lohar | AH6: =N19 -> Sanghamitra Khairmode | AI6: =N20 -> Santosh Chakraborty | AJ6: =N21 -> Vaishnavi Chothe | AK6: =N22 -> Vishakha Sali | AL6: =N23 -> T4 | AM6: =N24 -> T5 | AN6: =N25 -> T6 | AO6: =N26 -> T7 | AP6: =N27 -> T8 | AQ6: =N28 -> T9 | AR6: =N29 -> T10 | AS6: =N30 -> T11 | AT6: =N31 -> T12 | AU6: =N32 -> X | AV6: =N33 -> Apeksha Bavake (Instant) | AW6: =N34 -> Barsha Sahu (Instant) | AX6: =N35 -> Bikash Sahoo (Instant) | AY6: =N36 -> Deepti Tiwari (Instant) | AZ6: =N37 -> Dipali Chandgude (Instant) | BA6: =N38 -> Hanumant Lahane (Instant) | BB6: =N39 -> Laxman (Instant) | BC6: =N40 -> Meenakshi Devikar (Instant) | BD6: =N41 -> Nikita Nirmal (Instant) | BE6: =N42 -> Prasanna Hegde (Instant) | BF6: =N43 -> Pravin Patil (Instant) | BG6: =N44 -> Saman Lohar (Instant) | BH6: =N45 -> Sanghamitra Khairmode (Instant) | BI6: =N46 -> Santosh Chakraborty (Instant) | BJ6: =N47 -> Vaishnavi Chothe (Instant) | BK6: =N48 -> Vishakha Sali (Instant) | BL6: =N49 -> T16 | BM6: =N50 -> T17 | BN6: =N51 -> T18 | BO6: =N52 -> T19 | BP6: =N53 -> T20 | BQ6: =N54 -> T21 | BR6: =N55 -> T22 | BS6: =N56 -> T23
K7: =COUNTA(D7:J7)*C7 -> 0 | M7: 1 | N7: =Tutor_Names!B2 -> Apeksha Bavake | O7: =HLOOKUP($N7,$V$6:$BS$37,32,FALSE) -> 0 | P7: =HLOOKUP($N7,$V$45:$BS$77,32,FALSE) -> 0 | Q7: =SUM(O7:P7) -> 0 | V7: =COUNTIF($D7:$J7,V$6)*$C7 -> 0 | W7: =COUNTIF($D7:$J7,W$6)*$C7 -> 0 | X7: =COUNTIF($D7:$J7,X$6)*$C7 -> 0 | Y7: =COUNTIF($D7:$J7,Y$6)*$C7 -> 0 | Z7: =COUNTIF($D7:$J7,Z$6)*$C7 -> 0 | AA7: =COUNTIF($D7:$J7,AA$6)*$C7 -> 0 | AB7: =COUNTIF($D7:$J7,AB$6)*$C7 -> 0 | AC7: =COUNTIF($D7:$J7,AC$6)*$C7 -> 0 | ... BS7: =COUNTIF($D7:$J7,BS$6)*$C7 -> 0
K8: =COUNTA(D8:J8)*C8 -> 0 | M8: =M7+1 -> 2 | N8: =Tutor_Names!B3 -> Barsha Sahu | O8: =HLOOKUP($N8,$V$6:$BS$37,32,FALSE) -> 0 | P8: =HLOOKUP($N8,$V$45:$BS$77,32,FALSE) -> 0 | Q8: =SUM(O8:P8) -> 0 | V8: =COUNTIF($D8:$J8,V$6)*$C8 -> 0 | W8: =COUNTIF($D8:$J8,W$6)*$C8 -> 0 | X8: =COUNTIF($D8:$J8,X$6)*$C8 -> 0 | Y8: =COUNTIF($D8:$J8,Y$6)*$C8 -> 0 | Z8: =COUNTIF($D8:$J8,Z$6)*$C8 -> 0 | AA8: =COUNTIF($D8:$J8,AA$6)*$C8 -> 0 | AB8: =COUNTIF($D8:$J8,AB$6)*$C8 -> 0 | AC8: =COUNTIF($D8:$J8,AC$6)*$C8 -> 0 | ... BS8: =COUNTIF($D8:$J8,BS$6)*$C8 -> 0
K9: =COUNTA(D9:J9)*C9 -> 0 | M9: =M8+1 -> 3 | N9: =Tutor_Names!B4 -> Bikash Sahoo | O9: =HLOOKUP($N9,$V$6:$BS$37,32,FALSE) -> 0 | P9: =HLOOKUP($N9,$V$45:$BS$77,32,FALSE) -> 0 | Q9: =SUM(O9:P9) -> 0 | V9: =COUNTIF($D9:$J9,V$6)*$C9 -> 0 | W9: =COUNTIF($D9:$J9,W$6)*$C9 -> 0 | X9: =COUNTIF($D9:$J9,X$6)*$C9 -> 0 | Y9: =COUNTIF($D9:$J9,Y$6)*$C9 -> 0 | Z9: =COUNTIF($D9:$J9,Z$6)*$C9 -> 0 | AA9: =COUNTIF($D9:$J9,AA$6)*$C9 -> 0 | AB9: =COUNTIF($D9:$J9,AB$6)*$C9 -> 0 | AC9: =COUNTIF($D9:$J9,AC$6)*$C9 -> 0 | ... BS9: =COUNTIF($D9:$J9,BS$6)*$C9 -> 0
K10: =COUNTA(D10:J10)*C10 -> 0 | M10: =M9+1 -> 4 | N10: =Tutor_Names!B5 -> Deepti Tiwari | O10: =HLOOKUP($N10,$V$6:$BS$37,32,FALSE) -> 0 | P10: =HLOOKUP($N10,$V$45:$BS$77,32,FALSE) -> 0 | Q10: =SUM(O10:P10) -> 0 | V10: =COUNTIF($D10:$J10,V$6)*$C10 -> 0 | W10: =COUNTIF($D10:$J10,W$6)*$C10 -> 0 | X10: =COUNTIF($D10:$J10,X$6)*$C10 -> 0 | Y10: =COUNTIF($D10:$J10,Y$6)*$C10 -> 0 | Z10: =COUNTIF($D10:$J10,Z$6)*$C10 -> 0 | AA10: =COUNTIF($D10:$J10,AA$6)*$C10 -> 0 | AB10: =COUNTIF($D10:$J10,AB$6)*$C10 -> 0 | AC10: =COUNTIF($D10:$J10,AC$6)*$C10 -> 0 | ... BS10: =COUNTIF($D10:$J10,BS$6)*$C10 -> 0
K11: =COUNTA(D11:J11)*C11 -> 0 | M11: =M10+1 -> 5 | N11: =Tutor_Names!B6 -> Dipali Chandgude | O11: =HLOOKUP($N11,$V$6:$BS$37,32,FALSE) -> 0 | P11: =HLOOKUP($N11,$V$45:$BS$77,32,FALSE) -> 0 | Q11: =SUM(O11:P11) -> 0 | V11: =COUNTIF($D11:$J11,V$6)*$C11 -> 0 | W11: =COUNTIF($D11:$J11,W$6)*$C11 -> 0 | X11: =COUNTIF($D11:$J11,X$6)*$C11 -> 0 | Y11: =COUNTIF($D11:$J11,Y$6)*$C11 -> 0 | Z11: =COUNTIF($D11:$J11,Z$6)*$C11 -> 0 | AA11: =COUNTIF($D11:$J11,AA$6)*$C11 -> 0 | AB11: =COUNTIF($D11:$J11,AB$6)*$C11 -> 0 | AC11: =COUNTIF($D11:$J11,AC$6)*$C11 -> 0 | ... BS11: =COUNTIF($D11:$J11,BS$6)*$C11 -> 0
K12: =COUNTA(D12:J12)*C12 -> 0 | M12: =M11+1 -> 6 | N12: =Tutor_Names!B7 -> Hanumant Lahane | O12: =HLOOKUP($N12,$V$6:$BS$37,32,FALSE) -> 0 | P12: =HLOOKUP($N12,$V$45:$BS$77,32,FALSE) -> 0 | Q12: =SUM(O12:P12) -> 0 | V12: =COUNTIF($D12:$J12,V$6)*$C12 -> 0 | W12: =COUNTIF($D12:$J12,W$6)*$C12 -> 0 | X12: =COUNTIF($D12:$J12,X$6)*$C12 -> 0 | Y12: =COUNTIF($D12:$J12,Y$6)*$C12 -> 0 | Z12: =COUNTIF($D12:$J12,Z$6)*$C12 -> 0 | AA12: =COUNTIF($D12:$J12,AA$6)*$C12 -> 0 | AB12: =COUNTIF($D12:$J12,AB$6)*$C12 -> 0 | AC12: =COUNTIF($D12:$J12,AC$6)*$C12 -> 0 | ... BS12: =COUNTIF($D12:$J12,BS$6)*$C12 -> 0
K13: =COUNTA(D13:J13)*C13 -> 0 | M13: =M12+1 -> 7 | N13: =Tutor_Names!B8 -> Laxman | O13: =HLOOKUP($N13,$V$6:$BS$37,32,FALSE) -> 0 | P13: =HLOOKUP($N13,$V$45:$BS$77,32,FALSE) -> 0 | Q13: =SUM(O13:P13) -> 0 | V13: =COUNTIF($D13:$J13,V$6)*$C13 -> 0 | W13: =COUNTIF($D13:$J13,W$6)*$C13 -> 0 | X13: =COUNTIF($D13:$J13,X$6)*$C13 -> 0 | Y13: =COUNTIF($D13:$J13,Y$6)*$C13 -> 0 | Z13: =COUNTIF($D13:$J13,Z$6)*$C13 -> 0 | AA13: =COUNTIF($D13:$J13,AA$6)*$C13 -> 0 | AB13: =COUNTIF($D13:$J13,AB$6)*$C13 -> 0 | AC13: =COUNTIF($D13:$J13,AC$6)*$C13 -> 0 | ... BS13: =COUNTIF($D13:$J13,BS$6)*$C13 -> 0
K14: =COUNTA(D14:J14)*C14 -> 0 | M14: =M13+1 -> 8 | N14: =Tutor_Names!B9 -> Meenakshi Devikar | O14: =HLOOKUP($N14,$V$6:$BS$37,32,FALSE) -> 0 | P14: =HLOOKUP($N14,$V$45:$BS$77,32,FALSE) -> 0 | Q14: =SUM(O14:P14) -> 0 | V14: =COUNTIF($D14:$J14,V$6)*$C14 -> 0 | W14: =COUNTIF($D14:$J14,W$6)*$C14 -> 0 | X14: =COUNTIF($D14:$J14,X$6)*$C14 -> 0 | Y14: =COUNTIF($D14:$J14,Y$6)*$C14 -> 0 | Z14: =COUNTIF($D14:$J14,Z$6)*$C14 -> 0 | AA14: =COUNTIF($D14:$J14,AA$6)*$C14 -> 0 | AB14: =COUNTIF($D14:$J14,AB$6)*$C14 -> 0 | AC14: =COUNTIF($D14:$J14,AC$6)*$C14 -> 0 | ... BS14: =COUNTIF($D14:$J14,BS$6)*$C14 -> 0
K15: =COUNTA(D15:J15)*C15 -> 0 | M15: =M14+1 -> 9 | N15: =Tutor_Names!B10 -> Nikita Nirmal | O15: =HLOOKUP($N15,$V$6:$BS$37,32,FALSE) -> 0 | P15: =HLOOKUP($N15,$V$45:$BS$77,32,FALSE) -> 0 | Q15: =SUM(O15:P15) -> 0 | V15: =COUNTIF($D15:$J15,V$6)*$C15 -> 0 | W15: =COUNTIF($D15:$J15,W$6)*$C15 -> 0 | X15: =COUNTIF($D15:$J15,X$6)*$C15 -> 0 | Y15: =COUNTIF($D15:$J15,Y$6)*$C15 -> 0 | Z15: =COUNTIF($D15:$J15,Z$6)*$C15 -> 0 | AA15: =COUNTIF($D15:$J15,AA$6)*$C15 -> 0 | AB15: =COUNTIF($D15:$J15,AB$6)*$C15 -> 0 | AC15: =COUNTIF($D15:$J15,AC$6)*$C15 -> 0 | ... BS15: =COUNTIF($D15:$J15,BS$6)*$C15 -> 0
K16: =COUNTA(D16:J16)*C16 -> 0 | M16: =M15+1 -> 10 | N16: =Tutor_Names!B11 -> Prasanna Hegde | O16: =HLOOKUP($N16,$V$6:$BS$37,32,FALSE) -> 0 | P16: =HLOOKUP($N16,$V$45:$BS$77,32,FALSE) -> 0 | Q16: =SUM(O16:P16) -> 0 | V16: =COUNTIF($D16:$J16,V$6)*$C16 -> 0 | W16: =COUNTIF($D16:$J16,W$6)*$C16 -> 0 | X16: =COUNTIF($D16:$J16,X$6)*$C16 -> 0 | Y16: =COUNTIF($D16:$J16,Y$6)*$C16 -> 0 | Z16: =COUNTIF($D16:$J16,Z$6)*$C16 -> 0 | AA16: =COUNTIF($D16:$J16,AA$6)*$C16 -> 0 | AB16: =COUNTIF($D16:$J16,AB$6)*$C16 -> 0 | AC16: =COUNTIF($D16:$J16,AC$6)*$C16 -> 0 | ... BS16: =COUNTIF($D16:$J16,BS$6)*$C16 -> 0
K17: =COUNTA(D17:J17)*C17 -> 0 | M17: =M16+1 -> 11 | N17: =Tutor_Names!B12 -> Pravin Patil | O17: =HLOOKUP($N17,$V$6:$BS$37,32,FALSE) -> 0 | P17: =HLOOKUP($N17,$V$45:$BS$77,32,FALSE) -> 0 | Q17: =SUM(O17:P17) -> 0 | V17: =COUNTIF($D17:$J17,V$6)*$C17 -> 0 | W17: =COUNTIF($D17:$J17,W$6)*$C17 -> 0 | X17: =COUNTIF($D17:$J17,X$6)*$C17 -> 0 | Y17: =COUNTIF($D17:$J17,Y$6)*$C17 -> 0 | Z17: =COUNTIF($D17:$J17,Z$6)*$C17 -> 0 | AA17: =COUNTIF($D17:$J17,AA$6)*$C17 -> 0 | AB17: =COUNTIF($D17:$J17,AB$6)*$C17 -> 0 | AC17: =COUNTIF($D17:$J17,AC$6)*$C17 -> 0 | ... BS17: =COUNTIF($D17:$J17,BS$6)*$C17 -> 0
K18: =COUNTA(D18:J18)*C18 -> 0 | M18: =M17+1 -> 12 | N18: =Tutor_Names!B13 -> Saman Lohar | O18: =HLOOKUP($N18,$V$6:$BS$37,32,FALSE) -> 0 | P18: =HLOOKUP($N18,$V$45:$BS$77,32,FALSE) -> 0 | Q18: =SUM(O18:P18) -> 0 | V18: =COUNTIF($D18:$J18,V$6)*$C18 -> 0 | W18: =COUNTIF($D18:$J18,W$6)*$C18 -> 0 | X18: =COUNTIF($D18:$J18,X$6)*$C18 -> 0 | Y18: =COUNTIF($D18:$J18,Y$6)*$C18 -> 0 | Z18: =COUNTIF($D18:$J18,Z$6)*$C18 -> 0 | AA18: =COUNTIF($D18:$J18,AA$6)*$C18 -> 0 | AB18: =COUNTIF($D18:$J18,AB$6)*$C18 -> 0 | AC18: =COUNTIF($D18:$J18,AC$6)*$C18 -> 0 | ... BS18: =COUNTIF($D18:$J18,BS$6)*$C18 -> 0
K19: =COUNTA(D19:J19)*C19 -> 0 | M19: =M18+1 -> 13 | N19: =Tutor_Names!B14 -> Sanghamitra Khairmode | O19: =HLOOKUP($N19,$V$6:$BS$37,32,FALSE) -> 0 | P19: =HLOOKUP($N19,$V$45:$BS$77,32,FALSE) -> 0 | Q19: =SUM(O19:P19) -> 0 | V19: =COUNTIF($D19:$J19,V$6)*$C19 -> 0 | W19: =COUNTIF($D19:$J19,W$6)*$C19 -> 0 | X19: =COUNTIF($D19:$J19,X$6)*$C19 -> 0 | Y19: =COUNTIF($D19:$J19,Y$6)*$C19 -> 0 | Z19: =COUNTIF($D19:$J19,Z$6)*$C19 -> 0 | AA19: =COUNTIF($D19:$J19,AA$6)*$C19 -> 0 | AB19: =COUNTIF($D19:$J19,AB$6)*$C19 -> 0 | AC19: =COUNTIF($D19:$J19,AC$6)*$C19 -> 0 | ... BS19: =COUNTIF($D19:$J19,BS$6)*$C19 -> 0
... K36: =COUNTA(D36:J36)*C36 -> 0 | M36: =M35+1 -> 30 | N36: =Tutor_Names!B31 -> Deepti Tiwari (Instant) | O36: =HLOOKUP($N36,$V$6:$BS$37,32,FALSE) -> 0 | P36: =HLOOKUP($N36,$V$45:$BS$77,32,FALSE) -> 0 | Q36: =SUM(O36:P36) -> 0 | V36: =COUNTIF($D36:$J36,V$6)*$C36 -> 0 | W36: =COUNTIF($D36:$J36,W$6)*$C36 -> 0 | X36: =COUNTIF($D36:$J36,X$6)*$C36 -> 0 | Y36: =COUNTIF($D36:$J36,Y$6)*$C36 -> 0 | Z36: =COUNTIF($D36:$J36,Z$6)*$C36 -> 0 | AA36: =COUNTIF($D36:$J36,AA$6)*$C36 -> 0 | AB36: =COUNTIF($D36:$J36,AB$6)*$C36 -> 0 | AC36: =COUNTIF($D36:$J36,AC$6)*$C36 -> 0 | ... BS36: =COUNTIF($D36:$J36,BS$6)*$C36 -> 0
C37: DAYEND | K37: =SUM(K7:K36) -> 0 | M37: =M36+1 -> 31 | N37: =Tutor_Names!B32 -> Dipali Chandgude (Instant) | O37: =HLOOKUP($N37,$V$6:$BS$37,32,FALSE) -> 0 | P37: =HLOOKUP($N37,$V$45:$BS$77,32,FALSE) -> 0 | Q37: =SUM(O37:P37) -> 0 | V37: =SUM(V7:V36) -> 0 | W37: =SUM(W7:W36) -> 0 | X37: =SUM(X7:X36) -> 0 | Y37: =SUM(Y7:Y36) -> 0 | Z37: =SUM(Z7:Z36) -> 0 | AA37: =SUM(AA7:AA36) -> 0 | AB37: =SUM(AB7:AB36) -> 0 | AC37: =SUM(AC7:AC36) -> 0 | ... BS37: =SUM(BS7:BS36) -> 0
M38: =M37+1 -> 32 | N38: =Tutor_Names!B33 -> Hanumant Lahane (Instant) | O38: =HLOOKUP($N38,$V$6:$BS$37,32,FALSE) -> 0 | P38: =HLOOKUP($N38,$V$45:$BS$77,32,FALSE) -> 0 | Q38: =SUM(O38:P38) -> 0
M39: =M38+1 -> 33 | N39: =Tutor_Names!B34 -> Laxman (Instant) | O39: =HLOOKUP($N39,$V$6:$BS$37,32,FALSE) -> 0 | P39: =HLOOKUP($N39,$V$45:$BS$77,32,FALSE) -> 0 | Q39: =SUM(O39:P39) -> 0
M40: =M39+1 -> 34 | N40: =Tutor_Names!B35 -> Meenakshi Devikar (Instant) | O40: =HLOOKUP($N40,$V$6:$BS$37,32,FALSE) -> 0 | P40: =HLOOKUP($N40,$V$45:$BS$77,32,FALSE) -> 0 | Q40: =SUM(O40:P40) -> 0
B41: =B2 -> Week 1 | M41: =M40+1 -> 35 | N41: =Tutor_Names!B36 -> Nikita Nirmal (Instant) | O41: =HLOOKUP($N41,$V$6:$BS$37,32,FALSE) -> 0 | P41: =HLOOKUP($N41,$V$45:$BS$77,32,FALSE) -> 0 | Q41: =SUM(O41:P41) -> 0
B42: Night Shift (Pre-Scheduled) | M42: =M41+1 -> 36 | N42: =Tutor_Names!B37 -> Prasanna Hegde (Instant) | O42: =HLOOKUP($N42,$V$6:$BS$37,32,FALSE) -> 0 | P42: =HLOOKUP($N42,$V$45:$BS$77,32,FALSE) -> 0 | Q42: =SUM(O42:P42) -> 0
B43: Time | C43: Hours | D43: =D4 -> 0 | E43: =E4 -> 0 | F43: =F4 -> 0 | G43: =G4 -> 0 | H43: =H4 -> 0 | I43: =I4 -> 0 | J43: =J4 -> 46054 | K43: Total | M43: =M42+1 -> 37 | N43: =Tutor_Names!B38 -> Pravin Patil (Instant) | O43: =HLOOKUP($N43,$V$6:$BS$37,32,FALSE) -> 0 | P43: =HLOOKUP($N43,$V$45:$BS$77,32,FALSE) -> 0 | Q43: =SUM(O43:P43) -> 0
D44: Mon | E44: Tue | F44: Wed | G44: Thu | H44: Fri | I44: Sat | J44: Sun | M44: =M43+1 -> 38 | N44: =Tutor_Names!B39 -> Saman Lohar (Instant) | O44: =HLOOKUP($N44,$V$6:$BS$37,32,FALSE) -> 0 | P44: =HLOOKUP($N44,$V$45:$BS$77,32,FALSE) -> 0 | Q44: =SUM(O44:P44) -> 0
B45: Night Shift | C45: NIGHTSTART | M45: =M44+1 -> 39 | N45: =Tutor_Names!B40 -> Sanghamitra Khairmode (Instant) | O45: =HLOOKUP($N45,$V$6:$BS$37,32,FALSE) -> 0 | P45: =HLOOKUP($N45,$V$45:$BS$77,32,FALSE) -> 0 | Q45: =SUM(O45:P45) -> 0 | V45: =V6 -> Apeksha Bavake | W45: =W6 -> Barsha Sahu | X45: =X6 -> Bikash Sahoo | Y45: =Y6 -> Deepti Tiwari | Z45: =Z6 -> Dipali Chandgude | AA45: =AA6 -> Hanumant Lahane | AB45: =AB6 -> Laxman | AC45: =AC6 -> Meenakshi Devikar | ... BS45: =BS6 -> T23
K46: =COUNTA(D46:J46)*C46 -> 0 | M46: =M45+1 -> 40 | N46: =Tutor_Names!B41 -> Santosh Chakraborty (Instant) | O46: =HLOOKUP($N46,$V$6:$BS$37,32,FALSE) -> 0 | P46: =HLOOKUP($N46,$V$45:$BS$77,32,FALSE) -> 0 | Q46: =SUM(O46:P46) -> 0 | V46: =COUNTIF($D46:$J46,V$6)*$C46 -> 0 | W46: =COUNTIF($D46:$J46,W$6)*$C46 -> 0 | X46: =COUNTIF($D46:$J46,X$6)*$C46 -> 0 | Y46: =COUNTIF($D46:$J46,Y$6)*$C46 -> 0 | Z46: =COUNTIF($D46:$J46,Z$6)*$C46 -> 0 | AA46: =COUNTIF($D46:$J46,AA$6)*$C46 -> 0 | AB46: =COUNTIF($D46:$J46,AB$6)*$C46 -> 0 | AC46: =COUNTIF($D46:$J46,AC$6)*$C46 -> 0 | ... BS46: =COUNTIF($D46:$J46,BS$6)*$C46 -> 0
K47: =COUNTA(D47:J47)*C47 -> 0 | M47: =M46+1 -> 41 | N47: =Tutor_Names!B42 -> Vaishnavi Chothe (Instant) | O47: =HLOOKUP($N47,$V$6:$BS$37,32,FALSE) -> 0 | P47: =HLOOKUP($N47,$V$45:$BS$77,32,FALSE) -> 0 | Q47: =SUM(O47:P47) -> 0 | V47: =COUNTIF($D47:$J47,V$6)*$C47 -> 0 | W47: =COUNTIF($D47:$J47,W$6)*$C47 -> 0 | X47: =COUNTIF($D47:$J47,X$6)*$C47 -> 0 | Y47: =COUNTIF($D47:$J47,Y$6)*$C47 -> 0 | Z47: =COUNTIF($D47:$J47,Z$6)*$C47 -> 0 | AA47: =COUNTIF($D47:$J47,AA$6)*$C47 -> 0 | AB47: =COUNTIF($D47:$J47,AB$6)*$C47 -> 0 | AC47: =COUNTIF($D47:$J47,AC$6)*$C47 -> 0 | ... BS47: =COUNTIF($D47:$J47,BS$6)*$C47 -> 0
K48: =COUNTA(D48:J48)*C48 -> 0 | M48: =M47+1 -> 42 | N48: =Tutor_Names!B43 -> Vishakha Sali (Instant) | O48: =HLOOKUP($N48,$V$6:$BS$37,32,FALSE) -> 0 | P48: =HLOOKUP($N48,$V$45:$BS$77,32,FALSE) -> 0 | Q48: =SUM(O48:P48) -> 0 | V48: =COUNTIF($D48:$J48,V$6)*$C48 -> 0 | W48: =COUNTIF($D48:$J48,W$6)*$C48 -> 0 | X48: =COUNTIF($D48:$J48,X$6)*$C48 -> 0 | Y48: =COUNTIF($D48:$J48,Y$6)*$C48 -> 0 | Z48: =COUNTIF($D48:$J48,Z$6)*$C48 -> 0 | AA48: =COUNTIF($D48:$J48,AA$6)*$C48 -> 0 | AB48: =COUNTIF($D48:$J48,AB$6)*$C48 -> 0 | AC48: =COUNTIF($D48:$J48,AC$6)*$C48 -> 0 | ... BS48: =COUNTIF($D48:$J48,BS$6)*$C48 -> 0
K49: =COUNTA(D49:J49)*C49 -> 0 | M49: =M48+1 -> 43 | N49: =Tutor_Names!B44 -> T16 | O49: =HLOOKUP($N49,$V$6:$BS$37,32,FALSE) -> 0 | P49: =HLOOKUP($N49,$V$45:$BS$77,32,FALSE) -> 0 | Q49: =SUM(O49:P49) -> 0 | V49: =COUNTIF($D49:$J49,V$6)*$C49 -> 0 | W49: =COUNTIF($D49:$J49,W$6)*$C49 -> 0 | X49: =COUNTIF($D49:$J49,X$6)*$C49 -> 0 | Y49: =COUNTIF($D49:$J49,Y$6)*$C49 -> 0 | Z49: =COUNTIF($D49:$J49,Z$6)*$C49 -> 0 | AA49: =COUNTIF($D49:$J49,AA$6)*$C49 -> 0 | AB49: =COUNTIF($D49:$J49,AB$6)*$C49 -> 0 | AC49: =COUNTIF($D49:$J49,AC$6)*$C49 -> 0 | ... BS49: =COUNTIF($D49:$J49,BS$6)*$C49 -> 0
K50: =COUNTA(D50:J50)*C50 -> 0 | M50: =M49+1 -> 44 | N50: =Tutor_Names!B45 -> T17 | O50: =HLOOKUP($N50,$V$6:$BS$37,32,FALSE) -> 0 | P50: =HLOOKUP($N50,$V$45:$BS$77,32,FALSE) -> 0 | Q50: =SUM(O50:P50) -> 0 | V50: =COUNTIF($D50:$J50,V$6)*$C50 -> 0 | W50: =COUNTIF($D50:$J50,W$6)*$C50 -> 0 | X50: =COUNTIF($D50:$J50,X$6)*$C50 -> 0 | Y50: =COUNTIF($D50:$J50,Y$6)*$C50 -> 0 | Z50: =COUNTIF($D50:$J50,Z$6)*$C50 -> 0 | AA50: =COUNTIF($D50:$J50,AA$6)*$C50 -> 0 | AB50: =COUNTIF($D50:$J50,AB$6)*$C50 -> 0 | AC50: =COUNTIF($D50:$J50,AC$6)*$C50 -> 0 | ... BS50: =COUNTIF($D50:$J50,BS$6)*$C50 -> 0
K51: =COUNTA(D51:J51)*C51 -> 0 | M51: =M50+1 -> 45 | N51: =Tutor_Names!B46 -> T18 | O51: =HLOOKUP($N51,$V$6:$BS$37,32,FALSE) -> 0 | P51: =HLOOKUP($N51,$V$45:$BS$77,32,FALSE) -> 0 | Q51: =SUM(O51:P51) -> 0 | V51: =COUNTIF($D51:$J51,V$6)*$C51 -> 0 | W51: =COUNTIF($D51:$J51,W$6)*$C51 -> 0 | X51: =COUNTIF($D51:$J51,X$6)*$C51 -> 0 | Y51: =COUNTIF($D51:$J51,Y$6)*$C51 -> 0 | Z51: =COUNTIF($D51:$J51,Z$6)*$C51 -> 0 | AA51: =COUNTIF($D51:$J51,AA$6)*$C51 -> 0 | AB51: =COUNTIF($D51:$J51,AB$6)*$C51 -> 0 | AC51: =COUNTIF($D51:$J51,AC$6)*$C51 -> 0 | ... BS51: =COUNTIF($D51:$J51,BS$6)*$C51 -> 0
K52: =COUNTA(D52:J52)*C52 -> 0 | M52: =M51+1 -> 46 | N52: =Tutor_Names!B47 -> T19 | O52: =HLOOKUP($N52,$V$6:$BS$37,32,FALSE) -> 0 | P52: =HLOOKUP($N52,$V$45:$BS$77,32,FALSE) -> 0 | Q52: =SUM(O52:P52) -> 0 | V52: =COUNTIF($D52:$J52,V$6)*$C52 -> 0 | W52: =COUNTIF($D52:$J52,W$6)*$C52 -> 0 | X52: =COUNTIF($D52:$J52,X$6)*$C52 -> 0 | Y52: =COUNTIF($D52:$J52,Y$6)*$C52 -> 0 | Z52: =COUNTIF($D52:$J52,Z$6)*$C52 -> 0 | AA52: =COUNTIF($D52:$J52,AA$6)*$C52 -> 0 | AB52: =COUNTIF($D52:$J52,AB$6)*$C52 -> 0 | AC52: =COUNTIF($D52:$J52,AC$6)*$C52 -> 0 | ... BS52: =COUNTIF($D52:$J52,BS$6)*$C52 -> 0
K53: =COUNTA(D53:J53)*C53 -> 0 | M53: =M52+1 -> 47 | N53: =Tutor_Names!B48 -> T20 | O53: =HLOOKUP($N53,$V$6:$BS$37,32,FALSE) -> 0 | P53: =HLOOKUP($N53,$V$45:$BS$77,32,FALSE) -> 0 | Q53: =SUM(O53:P53) -> 0 | V53: =COUNTIF($D53:$J53,V$6)*$C53 -> 0 | W53: =COUNTIF($D53:$J53,W$6)*$C53 -> 0 | X53: =COUNTIF($D53:$J53,X$6)*$C53 -> 0 | Y53: =COUNTIF($D53:$J53,Y$6)*$C53 -> 0 | Z53: =COUNTIF($D53:$J53,Z$6)*$C53 -> 0 | AA53: =COUNTIF($D53:$J53,AA$6)*$C53 -> 0 | AB53: =COUNTIF($D53:$J53,AB$6)*$C53 -> 0 | AC53: =COUNTIF($D53:$J53,AC$6)*$C53 -> 0 | ... BS53: =COUNTIF($D53:$J53,BS$6)*$C53 -> 0
K54: =COUNTA(D54:J54)*C54 -> 0 | M54: =M53+1 -> 48 | N54: =Tutor_Names!B49 -> T21 | O54: =HLOOKUP($N54,$V$6:$BS$37,32,FALSE) -> 0 | P54: =HLOOKUP($N54,$V$45:$BS$77,32,FALSE) -> 0 | Q54: =SUM(O54:P54) -> 0 | V54: =COUNTIF($D54:$J54,V$6)*$C54 -> 0 | W54: =COUNTIF($D54:$J54,W$6)*$C54 -> 0 | X54: =COUNTIF($D54:$J54,X$6)*$C54 -> 0 | Y54: =COUNTIF($D54:$J54,Y$6)*$C54 -> 0 | Z54: =COUNTIF($D54:$J54,Z$6)*$C54 -> 0 | AA54: =COUNTIF($D54:$J54,AA$6)*$C54 -> 0 | AB54: =COUNTIF($D54:$J54,AB$6)*$C54 -> 0 | AC54: =COUNTIF($D54:$J54,AC$6)*$C54 -> 0 | ... BS54: =COUNTIF($D54:$J54,BS$6)*$C54 -> 0
K55: =COUNTA(D55:J55)*C55 -> 0 | M55: =M54+1 -> 49 | N55: =Tutor_Names!B50 -> T22 | O55: =HLOOKUP($N55,$V$6:$BS$37,32,FALSE) -> 0 | P55: =HLOOKUP($N55,$V$45:$BS$77,32,FALSE) -> 0 | Q55: =SUM(O55:P55) -> 0 | V55: =COUNTIF($D55:$J55,V$6)*$C55 -> 0 | W55: =COUNTIF($D55:$J55,W$6)*$C55 -> 0 | X55: =COUNTIF($D55:$J55,X$6)*$C55 -> 0 | Y55: =COUNTIF($D55:$J55,Y$6)*$C55 -> 0 | Z55: =COUNTIF($D55:$J55,Z$6)*$C55 -> 0 | AA55: =COUNTIF($D55:$J55,AA$6)*$C55 -> 0 | AB55: =COUNTIF($D55:$J55,AB$6)*$C55 -> 0 | AC55: =COUNTIF($D55:$J55,AC$6)*$C55 -> 0 | ... BS55: =COUNTIF($D55:$J55,BS$6)*$C55 -> 0
K56: =COUNTA(D56:J56)*C56 -> 0 | M56: =M55+1 -> 50 | N56: =Tutor_Names!B51 -> T23 | O56: =HLOOKUP($N56,$V$6:$BS$37,32,FALSE) -> 0 | P56: =HLOOKUP($N56,$V$45:$BS$77,32,FALSE) -> 0 | Q56: =SUM(O56:P56) -> 0 | V56: =COUNTIF($D56:$J56,V$6)*$C56 -> 0 | W56: =COUNTIF($D56:$J56,W$6)*$C56 -> 0 | X56: =COUNTIF($D56:$J56,X$6)*$C56 -> 0 | Y56: =COUNTIF($D56:$J56,Y$6)*$C56 -> 0 | Z56: =COUNTIF($D56:$J56,Z$6)*$C56 -> 0 | AA56: =COUNTIF($D56:$J56,AA$6)*$C56 -> 0 | AB56: =COUNTIF($D56:$J56,AB$6)*$C56 -> 0 | AC56: =COUNTIF($D56:$J56,AC$6)*$C56 -> 0 | ... BS56: =COUNTIF($D56:$J56,BS$6)*$C56 -> 0
...

Sheet PreSch_Wk_2
B1: =#REF! -> #REF!
B2: Week 2
B3: Day Shift (Pre-Scheduled)
B4: Time | C4: Hours | D4: 46055 | E4: 46056 | F4: 46057 | G4: 46058 | H4: 46059 | I4: 46060 | J4: 46061 | K4: Total
D5: Mon | E5: Tue | F5: Wed | G5: Thu | H5: Fri | I5: Sat | J5: Sun
B6: Day Shift | C6: DAYSTART | M6: Sr. No. | N6: Name of Tutor | O6: Day Shift Hours | P6: Night Shift Hours | Q6: Total Hours | V6: =N7 -> Apeksha Bavake | W6: =N8 -> Barsha Sahu | X6: =N9 -> Bikash Sahoo | Y6: =N10 -> Deepti Tiwari | Z6: =N11 -> Dipali Chandgude | AA6: =N12 -> Hanumant Lahane | AB6: =N13 -> Laxman | AC6: =N14 -> Meenakshi Devikar | AD6: =N15 -> Nikita Nirmal | AE6: =N16 -> Prasanna Hegde | AF6: =N17 -> Pravin Patil | AG6: =N18 -> Saman Lohar | AH6: =N19 -> Sanghamitra Khairmode | AI6: =N20 -> Santosh Chakraborty | AJ6: =N21 -> Vaishnavi Chothe | AK6: =N22 -> Vishakha Sali | AL6: =N23 -> T4 | AM6: =N24 -> T5 | AN6: =N25 -> T6 | AO6: =N26 -> T7 | AP6: =N27 -> T8 | AQ6: =N28 -> T9 | AR6: =N29 -> T10 | AS6: =N30 -> T11 | AT6: =N31 -> T12 | AU6: =N32 -> X | AV6: =N33 -> Apeksha Bavake (Instant) | AW6: =N34 -> Barsha Sahu (Instant) | AX6: =N35 -> Bikash Sahoo (Instant) | AY6: =N36 -> Deepti Tiwari (Instant) | AZ6: =N37 -> Dipali Chandgude (Instant) | BA6: =N38 -> Hanumant Lahane (Instant) | BB6: =N39 -> Laxman (Instant) | BC6: =N40 -> Meenakshi Devikar (Instant) | BD6: =N41 -> Nikita Nirmal (Instant) | BE6: =N42 -> Prasanna Hegde (Instant) | BF6: =N43 -> Pravin Patil (Instant) | BG6: =N44 -> Saman Lohar (Instant) | BH6: =N45 -> Sanghamitra Khairmode (Instant) | BI6: =N46 -> Santosh Chakraborty (Instant) | BJ6: =N47 -> Vaishnavi Chothe (Instant) | BK6: =N48 -> Vishakha Sali (Instant) | BL6: =N49 -> T16 | BM6: =N50 -> T17 | BN6: =N51 -> T18 | BO6: =N52 -> T19 | BP6: =N53 -> T20 | BQ6: =N54 -> T21 | BR6: =N55 -> T22 | BS6: =N56 -> T23
K7: =COUNTA(D7:J7)*C7 -> 0 | M7: 1 | N7: =Tutor_Names!B2 -> Apeksha Bavake | O7: =HLOOKUP($N7,$V$6:$BS$37,32,FALSE) -> 0 | P7: =HLOOKUP($N7,$V$45:$BS$77,32,FALSE) -> 0 | Q7: =SUM(O7:P7) -> 0 | V7: =COUNTIF($D7:$J7,V$6)*$C7 -> 0 | W7: =COUNTIF($D7:$J7,W$6)*$C7 -> 0 | X7: =COUNTIF($D7:$J7,X$6)*$C7 -> 0 | Y7: =COUNTIF($D7:$J7,Y$6)*$C7 -> 0 | Z7: =COUNTIF($D7:$J7,Z$6)*$C7 -> 0 | AA7: =COUNTIF($D7:$J7,AA$6)*$C7 -> 0 | AB7: =COUNTIF($D7:$J7,AB$6)*$C7 -> 0 | AC7: =COUNTIF($D7:$J7,AC$6)*$C7 -> 0 | ... BS7: =COUNTIF($D7:$J7,BS$6)*$C7 -> 0
K8: =COUNTA(D8:J8)*C8 -> 0 | M8: =M7+1 -> 2 | N8: =Tutor_Names!B3 -> Barsha Sahu | O8: =HLOOKUP($N8,$V$6:$BS$37,32,FALSE) -> 0 | P8: =HLOOKUP($N8,$V$45:$BS$77,32,FALSE) -> 0 | Q8: =SUM(O8:P8) -> 0 | V8: =COUNTIF($D8:$J8,V$6)*$C8 -> 0 | W8: =COUNTIF($D8:$J8,W$6)*$C8 -> 0 | X8: =COUNTIF($D8:$J8,X$6)*$C8 -> 0 | Y8: =COUNTIF($D8:$J8,Y$6)*$C8 -> 0 | Z8: =COUNTIF($D8:$J8,Z$6)*$C8 -> 0 | AA8: =COUNTIF($D8:$J8,AA$6)*$C8 -> 0 | AB8: =COUNTIF($D8:$J8,AB$6)*$C8 -> 0 | AC8: =COUNTIF($D8:$J8,AC$6)*$C8 -> 0 | ... BS8: =COUNTIF($D8:$J8,BS$6)*$C8 -> 0
K9: =COUNTA(D9:J9)*C9 -> 0 | M9: =M8+1 -> 3 | N9: =Tutor_Names!B4 -> Bikash Sahoo | O9: =HLOOKUP($N9,$V$6:$BS$37,32,FALSE) -> 0 | P9: =HLOOKUP($N9,$V$45:$BS$77,32,FALSE) -> 0 | Q9: =SUM(O9:P9) -> 0 | V9: =COUNTIF($D9:$J9,V$6)*$C9 -> 0 | W9: =COUNTIF($D9:$J9,W$6)*$C9 -> 0 | X9: =COUNTIF($D9:$J9,X$6)*$C9 -> 0 | Y9: =COUNTIF($D9:$J9,Y$6)*$C9 -> 0 | Z9: =COUNTIF($D9:$J9,Z$6)*$C9 -> 0 | AA9: =COUNTIF($D9:$J9,AA$6)*$C9 -> 0 | AB9: =COUNTIF($D9:$J9,AB$6)*$C9 -> 0 | AC9: =COUNTIF($D9:$J9,AC$6)*$C9 -> 0 | ... BS9: =COUNTIF($D9:$J9,BS$6)*$C9 -> 0
K10: =COUNTA(D10:J10)*C10 -> 0 | M10: =M9+1 -> 4 | N10: =Tutor_Names!B5 -> Deepti Tiwari | O10: =HLOOKUP($N10,$V$6:$BS$37,32,FALSE) -> 0 | P10: =HLOOKUP($N10,$V$45:$BS$77,32,FALSE) -> 0 | Q10: =SUM(O10:P10) -> 0 | V10: =COUNTIF($D10:$J10,V$6)*$C10 -> 0 | W10: =COUNTIF($D10:$J10,W$6)*$C10 -> 0 | X10: =COUNTIF($D10:$J10,X$6)*$C10 -> 0 | Y10: =COUNTIF($D10:$J10,Y$6)*$C10 -> 0 | Z10: =COUNTIF($D10:$J10,Z$6)*$C10 -> 0 | AA10: =COUNTIF($D10:$J10,AA$6)*$C10 -> 0 | AB10: =COUNTIF($D10:$J10,AB$6)*$C10 -> 0 | AC10: =COUNTIF($D10:$J10,AC$6)*$C10 -> 0 | ... BS10: =COUNTIF($D10:$J10,BS$6)*$C10 -> 0
K11: =COUNTA(D11:J11)*C11 -> 0 | M11: =M10+1 -> 5 | N11: =Tutor_Names!B6 -> Dipali Chandgude | O11: =HLOOKUP($N11,$V$6:$BS$37,32,FALSE) -> 0 | P11: =HLOOKUP($N11,$V$45:$BS$77,32,FALSE) -> 0 | Q11: =SUM(O11:P11) -> 0 | V11: =COUNTIF($D11:$J11,V$6)*$C11 -> 0 | W11: =COUNTIF($D11:$J11,W$6)*$C11 -> 0 | X11: =COUNTIF($D11:$J11,X$6)*$C11 -> 0 | Y11: =COUNTIF($D11:$J11,Y$6)*$C11 -> 0 | Z11: =COUNTIF($D11:$J11,Z$6)*$C11 -> 0 | AA11: =COUNTIF($D11:$J11,AA$6)*$C11 -> 0 | AB11: =COUNTIF($D11:$J11,AB$6)*$C11 -> 0 | AC11: =COUNTIF($D11:$J11,AC$6)*$C11 -> 0 | ... BS11: =COUNTIF($D11:$J11,BS$6)*$C11 -> 0
K12: =COUNTA(D12:J12)*C12 -> 0 | M12: =M11+1 -> 6 | N12: =Tutor_Names!B7 -> Hanumant Lahane | O12: =HLOOKUP($N12,$V$6:$BS$37,32,FALSE) -> 0 | P12: =HLOOKUP($N12,$V$45:$BS$77,32,FALSE) -> 0 | Q12: =SUM(O12:P12) -> 0 | V12: =COUNTIF($D12:$J12,V$6)*$C12 -> 0 | W12: =COUNTIF($D12:$J12,W$6)*$C12 -> 0 | X12: =COUNTIF($D12:$J12,X$6)*$C12 -> 0 | Y12: =COUNTIF($D12:$J12,Y$6)*$C12 -> 0 | Z12: =COUNTIF($D12:$J12,Z$6)*$C12 -> 0 | AA12: =COUNTIF($D12:$J12,AA$6)*$C12 -> 0 | AB12: =COUNTIF($D12:$J12,AB$6)*$C12 -> 0 | AC12: =COUNTIF($D12:$J12,AC$6)*$C12 -> 0 | ... BS12: =COUNTIF($D12:$J12,BS$6)*$C12 -> 0
K13: =COUNTA(D13:J13)*C13 -> 0 | M13: =M12+1 -> 7 | N13: =Tutor_Names!B8 -> Laxman | O13: =HLOOKUP($N13,$V$6:$BS$37,32,FALSE) -> 0 | P13: =HLOOKUP($N13,$V$45:$BS$77,32,FALSE) -> 0 | Q13: =SUM(O13:P13) -> 0 | V13: =COUNTIF($D13:$J13,V$6)*$C13 -> 0 | W13: =COUNTIF($D13:$J13,W$6)*$C13 -> 0 | X13: =COUNTIF($D13:$J13,X$6)*$C13 -> 0 | Y13: =COUNTIF($D13:$J13,Y$6)*$C13 -> 0 | Z13: =COUNTIF($D13:$J13,Z$6)*$C13 -> 0 | AA13: =COUNTIF($D13:$J13,AA$6)*$C13 -> 0 | AB13: =COUNTIF($D13:$J13,AB$6)*$C13 -> 0 | AC13: =COUNTIF($D13:$J13,AC$6)*$C13 -> 0 | ... BS13: =COUNTIF($D13:$J13,BS$6)*$C13 -> 0
K14: =COUNTA(D14:J14)*C14 -> 0 | M14: =M13+1 -> 8 | N14: =Tutor_Names!B9 -> Meenakshi Devikar | O14: =HLOOKUP($N14,$V$6:$BS$37,32,FALSE) -> 0 | P14: =HLOOKUP($N14,$V$45:$BS$77,32,FALSE) -> 0 | Q14: =SUM(O14:P14) -> 0 | V14: =COUNTIF($D14:$J14,V$6)*$C14 -> 0 | W14: =COUNTIF($D14:$J14,W$6)*$C14 -> 0 | X14: =COUNTIF($D14:$J14,X$6)*$C14 -> 0 | Y14: =COUNTIF($D14:$J14,Y$6)*$C14 -> 0 | Z14: =COUNTIF($D14:$J14,Z$6)*$C14 -> 0 | AA14: =COUNTIF($D14:$J14,AA$6)*$C14 -> 0 | AB14: =COUNTIF($D14:$J14,AB$6)*$C14 -> 0 | AC14: =COUNTIF($D14:$J14,AC$6)*$C14 -> 0 | ... BS14: =COUNTIF($D14:$J14,BS$6)*$C14 -> 0
K15: =COUNTA(D15:J15)*C15 -> 0 | M15: =M14+1 -> 9 | N15: =Tutor_Names!B10 -> Nikita Nirmal | O15: =HLOOKUP($N15,$V$6:$BS$37,32,FALSE) -> 0 | P15: =HLOOKUP($N15,$V$45:$BS$77,32,FALSE) -> 0 | Q15: =SUM(O15:P15) -> 0 | V15: =COUNTIF($D15:$J15,V$6)*$C15 -> 0 | W15: =COUNTIF($D15:$J15,W$6)*$C15 -> 0 | X15: =COUNTIF($D15:$J15,X$6)*$C15 -> 0 | Y15: =COUNTIF($D15:$J15,Y$6)*$C15 -> 0 | Z15: =COUNTIF($D15:$J15,Z$6)*$C15 -> 0 | AA15: =COUNTIF($D15:$J15,AA$6)*$C15 -> 0 | AB15: =COUNTIF($D15:$J15,AB$6)*$C15 -> 0 | AC15: =COUNTIF($D15:$J15,AC$6)*$C15 -> 0 | ... BS15: =COUNTIF($D15:$J15,BS$6)*$C15 -> 0
K16: =COUNTA(D16:J16)*C16 -> 0 | M16: =M15+1 -> 10 | N16: =Tutor_Names!B11 -> Prasanna Hegde | O16: =HLOOKUP($N16,$V$6:$BS$37,32,FALSE) -> 0 | P16: =HLOOKUP($N16,$V$45:$BS$77,32,FALSE) -> 0 | Q16: =SUM(O16:P16) -> 0 | V16: =COUNTIF($D16:$J16,V$6)*$C16 -> 0 | W16: =COUNTIF($D16:$J16,W$6)*$C16 -> 0 | X16: =COUNTIF($D16:$J16,X$6)*$C16 -> 0 | Y16: =COUNTIF($D16:$J16,Y$6)*$C16 -> 0 | Z16: =COUNTIF($D16:$J16,Z$6)*$C16 -> 0 | AA16: =COUNTIF($D16:$J16,AA$6)*$C16 -> 0 | AB16: =COUNTIF($D16:$J16,AB$6)*$C16 -> 0 | AC16: =COUNTIF($D16:$J16,AC$6)*$C16 -> 0 | ... BS16: =COUNTIF($D16:$J16,BS$6)*$C16 -> 0
K17: =COUNTA(D17:J17)*C17 -> 0 | M17: =M16+1 -> 11 | N17: =Tutor_Names!B12 -> Pravin Patil | O17: =HLOOKUP($N17,$V$6:$BS$37,32,FALSE) -> 0 | P17: =HLOOKUP($N17,$V$45:$BS$77,32,FALSE) -> 0 | Q17: =SUM(O17:P17) -> 0 | V17: =COUNTIF($D17:$J17,V$6)*$C17 -> 0 | W17: =COUNTIF($D17:$J17,W$6)*$C17 -> 0 | X17: =COUNTIF($D17:$J17,X$6)*$C17 -> 0 | Y17: =COUNTIF($D17:$J17,Y$6)*$C17 -> 0 | Z17: =COUNTIF($D17:$J17,Z$6)*$C17 -> 0 | AA17: =COUNTIF($D17:$J17,AA$6)*$C17 -> 0 | AB17: =COUNTIF($D17:$J17,AB$6)*$C17 -> 0 | AC17: =COUNTIF($D17:$J17,AC$6)*$C17 -> 0 | ... BS17: =COUNTIF($D17:$J17,BS$6)*$C17 -> 0
K18: =COUNTA(D18:J18)*C18 -> 0 | M18: =M17+1 -> 12 | N18: =Tutor_Names!B13 -> Saman Lohar | O18: =HLOOKUP($N18,$V$6:$BS$37,32,FALSE) -> 0 | P18: =HLOOKUP($N18,$V$45:$BS$77,32,FALSE) -> 0 | Q18: =SUM(O18:P18) -> 0 | V18: =COUNTIF($D18:$J18,V$6)*$C18 -> 0 | W18: =COUNTIF($D18:$J18,W$6)*$C18 -> 0 | X18: =COUNTIF($D18:$J18,X$6)*$C18 -> 0 | Y18: =COUNTIF($D18:$J18,Y$6)*$C18 -> 0 | Z18: =COUNTIF($D18:$J18,Z$6)*$C18 -> 0 | AA18: =COUNTIF($D18:$J18,AA$6)*$C18 -> 0 | AB18: =COUNTIF($D18:$J18,AB$6)*$C18 -> 0 | AC18: =COUNTIF($D18:$J18,AC$6)*$C18 -> 0 | ... BS18: =COUNTIF($D18:$J18,BS$6)*$C18 -> 0
K19: =COUNTA(D19:J19)*C19 -> 0 | M19: =M18+1 -> 13 | N19: =Tutor_Names!B14 -> Sanghamitra Khairmode | O19: =HLOOKUP($N19,$V$6:$BS$37,32,FALSE) -> 0 | P19: =HLOOKUP($N19,$V$45:$BS$77,32,FALSE) -> 0 | Q19: =SUM(O19:P19) -> 0 | V19: =COUNTIF($D19:$J19,V$6)*$C19 -> 0 | W19: =COUNTIF($D19:$J19,W$6)*$C19 -> 0 | X19: =COUNTIF($D19:$J19,X$6)*$C19 -> 0 | Y19: =COUNTIF($D19:$J19,Y$6)*$C19 -> 0 | Z19: =COUNTIF($D19:$J19,Z$6)*$C19 -> 0 | AA19: =COUNTIF($D19:$J19,AA$6)*$C19 -> 0 | AB19: =COUNTIF($D19:$J19,AB$6)*$C19 -> 0 | AC19: =COUNTIF($D19:$J19,AC$6)*$C19 -> 0 | ... BS19: =COUNTIF($D19:$J19,BS$6)*$C19 -> 0
... K36: =COUNTA(D36:J36)*C36 -> 0 | M36: =M35+1 -> 30 | N36: =Tutor_Names!B31 -> Deepti Tiwari (Instant) | O36: =HLOOKUP($N36,$V$6:$BS$37,32,FALSE) -> 0 | P36: =HLOOKUP($N36,$V$45:$BS$77,32,FALSE) -> 0 | Q36: =SUM(O36:P36) -> 0 | V36: =COUNTIF($D36:$J36,V$6)*$C36 -> 0 | W36: =COUNTIF($D36:$J36,W$6)*$C36 -> 0 | X36: =COUNTIF($D36:$J36,X$6)*$C36 -> 0 | Y36: =COUNTIF($D36:$J36,Y$6)*$C36 -> 0 | Z36: =COUNTIF($D36:$J36,Z$6)*$C36 -> 0 | AA36: =COUNTIF($D36:$J36,AA$6)*$C36 -> 0 | AB36: =COUNTIF($D36:$J36,AB$6)*$C36 -> 0 | AC36: =COUNTIF($D36:$J36,AC$6)*$C36 -> 0 | ... BS36: =COUNTIF($D36:$J36,BS$6)*$C36 -> 0
C37: DAYEND | K37: =SUM(K7:K36) -> 0 | M37: =M36+1 -> 31 | N37: =Tutor_Names!B32 -> Dipali Chandgude (Instant) | O37: =HLOOKUP($N37,$V$6:$BS$37,32,FALSE) -> 0 | P37: =HLOOKUP($N37,$V$45:$BS$77,32,FALSE) -> 0 | Q37: =SUM(O37:P37) -> 0 | V37: =SUM(V7:V36) -> 0 | W37: =SUM(W7:W36) -> 0 | X37: =SUM(X7:X36) -> 0 | Y37: =SUM(Y7:Y36) -> 0 | Z37: =SUM(Z7:Z36) -> 0 | AA37: =SUM(AA7:AA36) -> 0 | AB37: =SUM(AB7:AB36) -> 0 | AC37: =SUM(AC7:AC36) -> 0 | ... BS37: =SUM(BS7:BS36) -> 0
M38: =M37+1 -> 32 | N38: =Tutor_Names!B33 -> Hanumant Lahane (Instant) | O38: =HLOOKUP($N38,$V$6:$BS$37,32,FALSE) -> 0 | P38: =HLOOKUP($N38,$V$45:$BS$77,32,FALSE) -> 0 | Q38: =SUM(O38:P38) -> 0
M39: =M38+1 -> 33 | N39: =Tutor_Names!B34 -> Laxman (Instant) | O39: =HLOOKUP($N39,$V$6:$BS$37,32,FALSE) -> 0 | P39: =HLOOKUP($N39,$V$45:$BS$77,32,FALSE) -> 0 | Q39: =SUM(O39:P39) -> 0
M40: =M39+1 -> 34 | N40: =Tutor_Names!B35 -> Meenakshi Devikar (Instant) | O40: =HLOOKUP($N40,$V$6:$BS$37,32,FALSE) -> 0 | P40: =HLOOKUP($N40,$V$45:$BS$77,32,FALSE) -> 0 | Q40: =SUM(O40:P40) -> 0
B41: =B2 -> Week 2 | M41: =M40+1 -> 35 | N41: =Tutor_Names!B36 -> Nikita Nirmal (Instant) | O41: =HLOOKUP($N41,$V$6:$BS$37,32,FALSE) -> 0 | P41: =HLOOKUP($N41,$V$45:$BS$77,32,FALSE) -> 0 | Q41: =SUM(O41:P41) -> 0
B42: Night Shift (Pre-Scheduled) | M42: =M41+1 -> 36 | N42: =Tutor_Names!B37 -> Prasanna Hegde (Instant) | O42: =HLOOKUP($N42,$V$6:$BS$37,32,FALSE) -> 0 | P42: =HLOOKUP($N42,$V$45:$BS$77,32,FALSE) -> 0 | Q42: =SUM(O42:P42) -> 0
B43: Time | C43: Hours | D43: =D4 -> 46055 | E43: =E4 -> 46056 | F43: =F4 -> 46057 | G43: =G4 -> 46058 | H43: =H4 -> 46059 | I43: =I4 -> 46060 | J43: =J4 -> 46061 | K43: Total | M43: =M42+1 -> 37 | N43: =Tutor_Names!B38 -> Pravin Patil (Instant) | O43: =HLOOKUP($N43,$V$6:$BS$37,32,FALSE) -> 0 | P43: =HLOOKUP($N43,$V$45:$BS$77,32,FALSE) -> 0 | Q43: =SUM(O43:P43) -> 0
D44: Mon | E44: Tue | F44: Wed | G44: Thu | H44: Fri | I44: Sat | J44: Sun | M44: =M43+1 -> 38 | N44: =Tutor_Names!B39 -> Saman Lohar (Instant) | O44: =HLOOKUP($N44,$V$6:$BS$37,32,FALSE) -> 0 | P44: =HLOOKUP($N44,$V$45:$BS$77,32,FALSE) -> 0 | Q44: =SUM(O44:P44) -> 0
B45: Night Shift | C45: NIGHTSTART | M45: =M44+1 -> 39 | N45: =Tutor_Names!B40 -> Sanghamitra Khairmode (Instant) | O45: =HLOOKUP($N45,$V$6:$BS$37,32,FALSE) -> 0 | P45: =HLOOKUP($N45,$V$45:$BS$77,32,FALSE) -> 0 | Q45: =SUM(O45:P45) -> 0 | V45: =V6 -> Apeksha Bavake | W45: =W6 -> Barsha Sahu | X45: =X6 -> Bikash Sahoo | Y45: =Y6 -> Deepti Tiwari | Z45: =Z6 -> Dipali Chandgude | AA45: =AA6 -> Hanumant Lahane | AB45: =AB6 -> Laxman | AC45: =AC6 -> Meenakshi Devikar | ... BS45: =BS6 -> T23
K46: =COUNTA(D46:J46)*C46 -> 0 | M46: =M45+1 -> 40 | N46: =Tutor_Names!B41 -> Santosh Chakraborty (Instant) | O46: =HLOOKUP($N46,$V$6:$BS$37,32,FALSE) -> 0 | P46: =HLOOKUP($N46,$V$45:$BS$77,32,FALSE) -> 0 | Q46: =SUM(O46:P46) -> 0 | V46: =COUNTIF($D46:$J46,V$6)*$C46 -> 0 | W46: =COUNTIF($D46:$J46,W$6)*$C46 -> 0 | X46: =COUNTIF($D46:$J46,X$6)*$C46 -> 0 | Y46: =COUNTIF($D46:$J46,Y$6)*$C46 -> 0 | Z46: =COUNTIF($D46:$J46,Z$6)*$C46 -> 0 | AA46: =COUNTIF($D46:$J46,AA$6)*$C46 -> 0 | AB46: =COUNTIF($D46:$J46,AB$6)*$C46 -> 0 | AC46: =COUNTIF($D46:$J46,AC$6)*$C46 -> 0 | ... BS46: =COUNTIF($D46:$J46,BS$6)*$C46 -> 0
K47: =COUNTA(D47:J47)*C47 -> 0 | M47: =M46+1 -> 41 | N47: =Tutor_Names!B42 -> Vaishnavi Chothe (Instant) | O47: =HLOOKUP($N47,$V$6:$BS$37,32,FALSE) -> 0 | P47: =HLOOKUP($N47,$V$45:$BS$77,32,FALSE) -> 0 | Q47: =SUM(O47:P47) -> 0 | V47: =COUNTIF($D47:$J47,V$6)*$C47 -> 0 | W47: =COUNTIF($D47:$J47,W$6)*$C47 -> 0 | X47: =COUNTIF($D47:$J47,X$6)*$C47 -> 0 | Y47: =COUNTIF($D47:$J47,Y$6)*$C47 -> 0 | Z47: =COUNTIF($D47:$J47,Z$6)*$C47 -> 0 | AA47: =COUNTIF($D47:$J47,AA$6)*$C47 -> 0 | AB47: =COUNTIF($D47:$J47,AB$6)*$C47 -> 0 | AC47: =COUNTIF($D47:$J47,AC$6)*$C47 -> 0 | ... BS47: =COUNTIF($D47:$J47,BS$6)*$C47 -> 0
K48: =COUNTA(D48:J48)*C48 -> 0 | M48: =M47+1 -> 42 | N48: =Tutor_Names!B43 -> Vishakha Sali (Instant) | O48: =HLOOKUP($N48,$V$6:$BS$37,32,FALSE) -> 0 | P48: =HLOOKUP($N48,$V$45:$BS$77,32,FALSE) -> 0 | Q48: =SUM(O48:P48) -> 0 | V48: =COUNTIF($D48:$J48,V$6)*$C48 -> 0 | W48: =COUNTIF($D48:$J48,W$6)*$C48 -> 0 | X48: =COUNTIF($D48:$J48,X$6)*$C48 -> 0 | Y48: =COUNTIF($D48:$J48,Y$6)*$C48 -> 0 | Z48: =COUNTIF($D48:$J48,Z$6)*$C48 -> 0 | AA48: =COUNTIF($D48:$J48,AA$6)*$C48 -> 0 | AB48: =COUNTIF($D48:$J48,AB$6)*$C48 -> 0 | AC48: =COUNTIF($D48:$J48,AC$6)*$C48 -> 0 | ... BS48: =COUNTIF($D48:$J48,BS$6)*$C48 -> 0
K49: =COUNTA(D49:J49)*C49 -> 0 | M49: =M48+1 -> 43 | N49: =Tutor_Names!B44 -> T16 | O49: =HLOOKUP($N49,$V$6:$BS$37,32,FALSE) -> 0 | P49: =HLOOKUP($N49,$V$45:$BS$77,32,FALSE) -> 0 | Q49: =SUM(O49:P49) -> 0 | V49: =COUNTIF($D49:$J49,V$6)*$C49 -> 0 | W49: =COUNTIF($D49:$J49,W$6)*$C49 -> 0 | X49: =COUNTIF($D49:$J49,X$6)*$C49 -> 0 | Y49: =COUNTIF($D49:$J49,Y$6)*$C49 -> 0 | Z49: =COUNTIF($D49:$J49,Z$6)*$C49 -> 0 | AA49: =COUNTIF($D49:$J49,AA$6)*$C49 -> 0 | AB49: =COUNTIF($D49:$J49,AB$6)*$C49 -> 0 | AC49: =COUNTIF($D49:$J49,AC$6)*$C49 -> 0 | ... BS49: =COUNTIF($D49:$J49,BS$6)*$C49 -> 0
K50: =COUNTA(D50:J50)*C50 -> 0 | M50: =M49+1 -> 44 | N50: =Tutor_Names!B45 -> T17 | O50: =HLOOKUP($N50,$V$6:$BS$37,32,FALSE) -> 0 | P50: =HLOOKUP($N50,$V$45:$BS$77,32,FALSE) -> 0 | Q50: =SUM(O50:P50) -> 0 | V50: =COUNTIF($D50:$J50,V$6)*$C50 -> 0 | W50: =COUNTIF($D50:$J50,W$6)*$C50 -> 0 | X50: =COUNTIF($D50:$J50,X$6)*$C50 -> 0 | Y50: =COUNTIF($D50:$J50,Y$6)*$C50 -> 0 | Z50: =COUNTIF($D50:$J50,Z$6)*$C50 -> 0 | AA50: =COUNTIF($D50:$J50,AA$6)*$C50 -> 0 | AB50: =COUNTIF($D50:$J50,AB$6)*$C50 -> 0 | AC50: =COUNTIF($D50:$J50,AC$6)*$C50 -> 0 | ... BS50: =COUNTIF($D50:$J50,BS$6)*$C50 -> 0
K51: =COUNTA(D51:J51)*C51 -> 0 | M51: =M50+1 -> 45 | N51: =Tutor_Names!B46 -> T18 | O51: =HLOOKUP($N51,$V$6:$BS$37,32,FALSE) -> 0 | P51: =HLOOKUP($N51,$V$45:$BS$77,32,FALSE) -> 0 | Q51: =SUM(O51:P51) -> 0 | V51: =COUNTIF($D51:$J51,V$6)*$C51 -> 0 | W51: =COUNTIF($D51:$J51,W$6)*$C51 -> 0 | X51: =COUNTIF($D51:$J51,X$6)*$C51 -> 0 | Y51: =COUNTIF($D51:$J51,Y$6)*$C51 -> 0 | Z51: =COUNTIF($D51:$J51,Z$6)*$C51 -> 0 | AA51: =COUNTIF($D51:$J51,AA$6)*$C51 -> 0 | AB51: =COUNTIF($D51:$J51,AB$6)*$C51 -> 0 | AC51: =COUNTIF($D51:$J51,AC$6)*$C51 -> 0 | ... BS51: =COUNTIF($D51:$J51,BS$6)*$C51 -> 0
K52: =COUNTA(D52:J52)*C52 -> 0 | M52: =M51+1 -> 46 | N52: =Tutor_Names!B47 -> T19 | O52: =HLOOKUP($N52,$V$6:$BS$37,32,FALSE) -> 0 | P52: =HLOOKUP($N52,$V$45:$BS$77,32,FALSE) -> 0 | Q52: =SUM(O52:P52) -> 0 | V52: =COUNTIF($D52:$J52,V$6)*$C52 -> 0 | W52: =COUNTIF($D52:$J52,W$6)*$C52 -> 0 | X52: =COUNTIF($D52:$J52,X$6)*$C52 -> 0 | Y52: =COUNTIF($D52:$J52,Y$6)*$C52 -> 0 | Z52: =COUNTIF($D52:$J52,Z$6)*$C52 -> 0 | AA52: =COUNTIF($D52:$J52,AA$6)*$C52 -> 0 | AB52: =COUNTIF($D52:$J52,AB$6)*$C52 -> 0 | AC52: =COUNTIF($D52:$J52,AC$6)*$C52 -> 0 | ... BS52: =COUNTIF($D52:$J52,BS$6)*$C52 -> 0
K53: =COUNTA(D53:J53)*C53 -> 0 | M53: =M52+1 -> 47 | N53: =Tutor_Names!B48 -> T20 | O53: =HLOOKUP($N53,$V$6:$BS$37,32,FALSE) -> 0 | P53: =HLOOKUP($N53,$V$45:$BS$77,32,FALSE) -> 0 | Q53: =SUM(O53:P53) -> 0 | V53: =COUNTIF($D53:$J53,V$6)*$C53 -> 0 | W53: =COUNTIF($D53:$J53,W$6)*$C53 -> 0 | X53: =COUNTIF($D53:$J53,X$6)*$C53 -> 0 | Y53: =COUNTIF($D53:$J53,Y$6)*$C53 -> 0 | Z53: =COUNTIF($D53:$J53,Z$6)*$C53 -> 0 | AA53: =COUNTIF($D53:$J53,AA$6)*$C53 -> 0 | AB53: =COUNTIF($D53:$J53,AB$6)*$C53 -> 0 | AC53: =COUNTIF($D53:$J53,AC$6)*$C53 -> 0 | ... BS53: =COUNTIF($D53:$J53,BS$6)*$C53 -> 0
K54: =COUNTA(D54:J54)*C54 -> 0 | M54: =M53+1 -> 48 | N54: =Tutor_Names!B49 -> T21 | O54: =HLOOKUP($N54,$V$6:$BS$37,32,FALSE) -> 0 | P54: =HLOOKUP($N54,$V$45:$BS$77,32,FALSE) -> 0 | Q54: =SUM(O54:P54) -> 0 | V54: =COUNTIF($D54:$J54,V$6)*$C54 -> 0 | W54: =COUNTIF($D54:$J54,W$6)*$C54 -> 0 | X54: =COUNTIF($D54:$J54,X$6)*$C54 -> 0 | Y54: =COUNTIF($D54:$J54,Y$6)*$C54 -> 0 | Z54: =COUNTIF($D54:$J54,Z$6)*$C54 -> 0 | AA54: =COUNTIF($D54:$J54,AA$6)*$C54 -> 0 | AB54: =COUNTIF($D54:$J54,AB$6)*$C54 -> 0 | AC54: =COUNTIF($D54:$J54,AC$6)*$C54 -> 0 | ... BS54: =COUNTIF($D54:$J54,BS$6)*$C54 -> 0
K55: =COUNTA(D55:J55)*C55 -> 0 | M55: =M54+1 -> 49 | N55: =Tutor_Names!B50 -> T22 | O55: =HLOOKUP($N55,$V$6:$BS$37,32,FALSE) -> 0 | P55: =HLOOKUP($N55,$V$45:$BS$77,32,FALSE) -> 0 | Q55: =SUM(O55:P55) -> 0 | V55: =COUNTIF($D55:$J55,V$6)*$C55 -> 0 | W55: =COUNTIF($D55:$J55,W$6)*$C55 -> 0 | X55: =COUNTIF($D55:$J55,X$6)*$C55 -> 0 | Y55: =COUNTIF($D55:$J55,Y$6)*$C55 -> 0 | Z55: =COUNTIF($D55:$J55,Z$6)*$C55 -> 0 | AA55: =COUNTIF($D55:$J55,AA$6)*$C55 -> 0 | AB55: =COUNTIF($D55:$J55,AB$6)*$C55 -> 0 | AC55: =COUNTIF($D55:$J55,AC$6)*$C55 -> 0 | ... BS55: =COUNTIF($D55:$J55,BS$6)*$C55 -> 0
K56: =COUNTA(D56:J56)*C56 -> 0 | M56: =M55+1 -> 50 | N56: =Tutor_Names!B51 -> T23 | O56: =HLOOKUP($N56,$V$6:$BS$37,32,FALSE) -> 0 | P56: =HLOOKUP($N56,$V$45:$BS$77,32,FALSE) -> 0 | Q56: =SUM(O56:P56) -> 0 | V56: =COUNTIF($D56:$J56,V$6)*$C56 -> 0 | W56: =COUNTIF($D56:$J56,W$6)*$C56 -> 0 | X56: =COUNTIF($D56:$J56,X$6)*$C56 -> 0 | Y56: =COUNTIF($D56:$J56,Y$6)*$C56 -> 0 | Z56: =COUNTIF($D56:$J56,Z$6)*$C56 -> 0 | AA56: =COUNTIF($D56:$J56,AA$6)*$C56 -> 0 | AB56: =COUNTIF($D56:$J56,AB$6)*$C56 -> 0 | AC56: =COUNTIF($D56:$J56,AC$6)*$C56 -> 0 | ... BS56: =COUNTIF($D56:$J56,BS$6)*$C56 -> 0
...

Sheet PreSch_Wk_3
B1: =#REF! -> #REF!
B2: Week 3
B3: Day Shift (Pre-Scheduled)
B4: Time | C4: Hours | D4: 46062 | E4: 46063 | F4: 46064 | G4: 46065 | H4: 46066 | I4: 46067 | J4: 46068 | K4: Total
D5: Mon | E5: Tue | F5: Wed | G5: Thu | H5: Fri | I5: Sat | J5: Sun
B6: Day Shift | C6: DAYSTART | M6: Sr. No. | N6: Name of Tutor | O6: Day Shift Hours | P6: Night Shift Hours | Q6: Total Hours | V6: =N7 -> Apeksha Bavake | W6: =N8 -> Barsha Sahu | X6: =N9 -> Bikash Sahoo | Y6: =N10 -> Deepti Tiwari | Z6: =N11 -> Dipali Chandgude | AA6: =N12 -> Hanumant Lahane | AB6: =N13 -> Laxman | AC6: =N14 -> Meenakshi Devikar | AD6: =N15 -> Nikita Nirmal | AE6: =N16 -> Prasanna Hegde | AF6: =N17 -> Pravin Patil | AG6: =N18 -> Saman Lohar | AH6: =N19 -> Sanghamitra Khairmode | AI6: =N20 -> Santosh Chakraborty | AJ6: =N21 -> Vaishnavi Chothe | AK6: =N22 -> Vishakha Sali | AL6: =N23 -> T4 | AM6: =N24 -> T5 | AN6: =N25 -> T6 | AO6: =N26 -> T7 | AP6: =N27 -> T8 | AQ6: =N28 -> T9 | AR6: =N29 -> T10 | AS6: =N30 -> T11 | AT6: =N31 -> T12 | AU6: =N32 -> X | AV6: =N33 -> Apeksha Bavake (Instant) | AW6: =N34 -> Barsha Sahu (Instant) | AX6: =N35 -> Bikash Sahoo (Instant) | AY6: =N36 -> Deepti Tiwari (Instant) | AZ6: =N37 -> Dipali Chandgude (Instant) | BA6: =N38 -> Hanumant Lahane (Instant) | BB6: =N39 -> Laxman (Instant) | BC6: =N40 -> Meenakshi Devikar (Instant) | BD6: =N41 -> Nikita Nirmal (Instant) | BE6: =N42 -> Prasanna Hegde (Instant) | BF6: =N43 -> Pravin Patil (Instant) | BG6: =N44 -> Saman Lohar (Instant) | BH6: =N45 -> Sanghamitra Khairmode (Instant) | BI6: =N46 -> Santosh Chakraborty (Instant) | BJ6: =N47 -> Vaishnavi Chothe (Instant) | BK6: =N48 -> Vishakha Sali (Instant) | BL6: =N49 -> T16 | BM6: =N50 -> T17 | BN6: =N51 -> T18 | BO6: =N52 -> T19 | BP6: =N53 -> T20 | BQ6: =N54 -> T21 | BR6: =N55 -> T22 | BS6: =N56 -> T23
